Workbook

Sheet LIST
A1: NO | B1: 名 | C1: 英 | D1: 出現 | E1: 特質 | F1: 結合 | G1: 作成日 | H1: 投稿日 | I1: 済 | J1: リール | K1: Column 11 | L1: LEN | M1: _ | N1: 1 | O1: 1_Len | P1: 2 | Q1: 2_Len | R1: 3 | S1: 3_Len | T1: 4_Len | U1: 5 | V1: 5_Len | W1: 4 | X1: 6 | Y1: 6_Len | Z1: 7 | AA1: 7_len | AB1: 8 | AC1: 8_len
A2: 0 | B2: 書楽斎（しょらくさい） | C2: syorakusai | D2: 寺子屋や筆屋の周辺 | E2: 丸い頭が光る妖怪。筆を手に持つ。 画は人造の巧智により描かれしものなれど、 文は我が筆の妙技により輝く珠として後に残らん。 我が志は、千体の妖怪を集め私蔵展を催すこと。 日々一体ずつ記し、仕事の御便りを待つ。 | F2: ="【名】" & B2 & C2 &char(10) & "【番】" & text(A2,"0000") & char(10) &"【出現】"&D2& char(10)&"【特質】"& char(10)&E2&char(10)&char(10)&memo!$B$1 -> 【名】書楽斎（しょらくさい）syorakusai 【番】0000 【出現】寺子屋や筆屋の周辺 【特質】 丸い頭が光る妖怪。筆を手に持つ。 画は人造の巧智により描かれしものなれど、 文は我が筆の妙技により輝く珠として後に残らん。 我が志は、千体の妖怪を集め私蔵展を催すこと。 日々一体ずつ記し、仕事の御便りを待つ。 #妖怪 #yokai #sumie #monster #ghost | G2: 45696 | H2: - | I2: - | J2: 45699 | K2: ふりかえるといるよ | L2: =len(E2) -> 104 | N2: =mid(F2,1,find("【特質】",F2)-1) &char(10)&memo!$B$2 -> 【名】書楽斎（しょらくさい）syorakusai 【番】0000 【出現】寺子屋や筆屋の周辺 #妖怪 #お化け #怪物 #オリジナル妖怪 #monster #ghost #妖怪好き #浮世絵 #百鬼夜行 | O2: =len(N2) -> 102 | P2: 丸い頭が光る妖怪。筆を手に持つ。 画は人造の巧智により描かるものなれど、 文は我が筆の妙技により輝く珠として後に残らん。 我が志は、千体の妖怪を集め私蔵展を催すこと。 日々一体ずつ記し、仕事の御便りを待つ。 | Q2: =len(P2) -> 108 | S2: =len(R2) -> 0 | T2: =len(W2) -> 0 | V2: =len(U2) -> 0 | Y2: =len(X2) -> 0 | AA2: =len(Z2) -> 0 | AC2: =len(AB2) -> 0
A3: 1 | B3: 左腕（ひだりで） | C3: hidaride | D3: 幼稚園や保育園、寺子屋、さらには夜の宿場町で休息を求める子供たちのそば | E3: ほっそりした体型の優しい男性の姿をしているが、左腕だけ異常に大きく発達し、抱き枕のような柔らかさを持つ。 職員不足の保育園や幼稚園に忍び込み、子供たちを優しく包み込んで寝かしつける。 子供は不思議とすぐに眠るため、寝かしつけの神として一部の保育士に密かに信仰されている。 通常は温厚だが、右手を触られると激高し、触れた者を捕食する。 過去に右手を縛られたり、傷を負わされたことがあり、それが原因で極端に右手を触られるのを嫌う。 決して右手には触れないこと。 「ありがとう」と囁きながら背を向けると、静かに立ち去る。 眠れぬ夜に「ひだりでよ、子を眠らせたまえ」と願うと現れることがある。 夜間保育施設で、子供たちが一斉に寝入る怪現象が報告されている。 たまに育児に疲れた親の枕元にも現れるが、大人は眠らせてもらえない。 | F3: ="【名】" & B3 & C3 &char(10) & "【番】" & text(A3,"0000") & char(10) &"【出現】"&D3& char(10)&"【特質】"& char(10)&E3&char(10)&char(10)&memo!$B$1 -> 【名】左腕（ひだりで）hidaride 【番】0001 【出現】幼稚園や保育園、寺子屋、さらには夜の宿場町で休息を求める子供たちのそば 【特質】 ほっそりした体型の優しい男性の姿をしているが、左腕だけ異常に大きく発達し、抱き枕のような柔らかさを持つ。 職員不足の保育園や幼稚園に忍び込み、子供たちを優しく包み込んで寝かしつける。 子供は不思議とすぐに眠るため、寝かしつけの神として一部の保育士に密かに信仰されている。 通常は温厚だが、右手を触られると激高し、触れた者を捕食する。 過去に右手を縛られたり、傷を負わされたことがあり、それが原因で極端に右手を触られるのを嫌う。 決して右手には触れないこと。 「ありがとう」と囁きながら背を向けると、静かに立ち去る。 眠れぬ夜に「ひだりでよ、子を眠らせたまえ」と願うと現れることがある。 夜間保育施設で、子供たちが一斉に寝入る怪現象が報告されている。 たまに育児に疲れた親の枕元にも現れるが、大人は眠らせてもらえない。 #妖怪 #yokai #sumie #monster #ghost | G3: 45694 | H3: 45694 | I3: ○ | J3: - | L3: =len(E3) -> 379 | N3: =mid(F3,1,find("【特質】",F3)-1) &char(10)&memo!$B$2 -> 【名】左腕（ひだりで）hidaride 【番】0001 【出現】幼稚園や保育園、寺子屋、さらには夜の宿場町で休息を求める子供たちのそば #妖怪 #お化け #怪物 #オリジナル妖怪 #monster #ghost #妖怪好き #浮世絵 #百鬼夜行 | O3: =len(N3) -> 123 | P3: ほっそりした体型の優しい男性の姿をしているが、左腕だけ異常に大きく発達し、抱き枕のような柔らかさを持つ。 職員不足の保育園や幼稚園に忍び込み、子供たちを優しく包み込んで寝かしつける。 子供は不思議とすぐに眠るため、寝かしつけの神として一部の保育士に密かに信仰されている。 | Q3: =len(P3) -> 136 | R3: 通常は温厚だが、右手を触られると激高し、触れた者を捕食する。 過去に右手を縛られたり、傷を負わされたことがあり、それが原因で極端に右手を触られるのを嫌う。 決して右手には触れないこと。 「ありがとう」と囁きながら背を向けると、静かに立ち去る。 | S3: =len(R3) -> 122 | T3: =len(W3) -> 102 | V3: =len(U3) -> 0 | W3: 眠れぬ夜に「ひだりでよ、子を眠らせたまえ」と願うと現れることがある。 夜間保育施設で、子供たちが一斉に寝入る怪現象が報告されている。 たまに育児に疲れた親の枕元にも現れるが、大人は眠らせてもらえない。 | Y3: =len(X3) -> 0 | AA3: =len(Z3) -> 0 | AC3: =len(AB3) -> 0
A4: 2 | B4: 出汁搾（だししぼ） | C4: dashishibo | D4: 沿岸の海底や潮だまり、時には漁村の沖合 | E4: 深海に生息する巨大な昆布の妖怪。 普通の昆布とは異なり、意思を持ち、人間の言葉を理解することができる。 しかし、最大の特徴は「常に出汁を放出し続ける」という体質。どれほど努力しても止めることはできず、じわじわと旨味が溢れ出してしまう。 そのため、海中では常に出汁の香りが漂い、無数の魚たちが群がってくる。 出汁搾本人はこの体質に悩んでおり、「俺だって普通の海藻として静かに暮らしたいのに……」と嘆いているが、魚たちはお構いなしに周囲を泳ぎ回り、時にはその体をついばんでしまうことも。 ある時、漁師たちはこの噂を聞きつけ、出汁搾を捕まえようとした。 しかし、捕まえてもなお出汁は止まらず、村中が絶品の味わいに包まれたため、結果として漁師たちは大いに喜んだという。 出汁搾自身は「やめろ……もう何も搾り取らないでくれ……」と涙を浮かべていたとか。 出汁搾を捕まえると、その村はしばらく食に困らなくなると言われているが、あまりに長く搾りすぎると、出汁が枯渇し、哀れな姿になってしまう。 そのため、村の者たちは一定の期間が過ぎると「もういいから海に帰れ」と海へ戻してやるのが習わしとなっていた。 もし海で出汁の香りが漂ってきたら、それは出汁搾が近くにいる証拠かもしれない。 しかし、あまりに近づきすぎると、「お前も俺の出汁に引き寄せられたのか……」と悲しげな目で見つめられることになるだろう。 | F4: ="【名】" & B4 & C4 &char(10) & "【番】" & text(A4,"0000") & char(10) &"【出現】"&D4& char(10)&"【特質】"& char(10)&E4&char(10)&char(10)&memo!$B$1 -> 【名】出汁搾（だししぼ）dashishibo 【番】0002 【出現】沿岸の海底や潮だまり、時には漁村の沖合 【特質】 深海に生息する巨大な昆布の妖怪。 普通の昆布とは異なり、意思を持ち、人間の言葉を理解することができる。 しかし、最大の特徴は「常に出汁を放出し続ける」という体質。どれほど努力しても止めることはできず、じわじわと旨味が溢れ出してしまう。 そのため、海中では常に出汁の香りが漂い、無数の魚たちが群がってくる。 出汁搾本人はこの体質に悩んでおり、「俺だって普通の海藻として静かに暮らしたいのに……」と嘆いているが、魚たちはお構いなしに周囲を泳ぎ回り、時にはその体をついばんでしまうことも。 ある時、漁師たちはこの噂を聞きつけ、出汁搾を捕まえようとした。 しかし、捕まえてもなお出汁は止まらず、村中が絶品の味わいに包まれたため、結果として漁師たちは大いに喜んだという。 出汁搾自身は「やめろ……もう何も搾り取らないでくれ……」と涙を浮かべていたとか。 出汁搾を捕まえると、その村はしばらく食に困らなくなると言われているが、あまりに長く搾りすぎると、出汁が枯渇し、哀れな姿になってしまう。 そのため、村の者たちは一定の期間が過ぎると「もういいから海に帰れ」と海へ戻してやるのが習わしとなっていた。 もし海で出汁の香りが漂ってきたら、それは出汁搾が近くにいる証拠かもしれない。 しかし、あまりに近づきすぎると、「お前も俺の出汁に引き寄せられたのか……」と悲しげな目で見つめられることになるだろう。 #妖怪 #yokai #sumie #monster #ghost | G4: 45694 | H4: 45695 | I4: ○ | J4: 45703 | K4: 透明人間 | L4: =len(E4) -> 599 | N4: =mid(F4,1,find("【特質】",F4)-1) &char(10)&memo!$B$2 -> 【名】出汁搾（だししぼ）dashishibo 【番】0002 【出現】沿岸の海底や潮だまり、時には漁村の沖合 #妖怪 #お化け #怪物 #オリジナル妖怪 #monster #ghost #妖怪好き #浮世絵 #百鬼夜行 | O4: =len(N4) -> 110 | P4: 深海に生息する巨大な昆布の妖怪。 普通の昆布とは異なり、意思を持ち、人間の言葉を理解することができる。 しかし、最大の特徴は「常に出汁を放出し続ける」という体質。どれほど努力しても止めることはできず、じわじわと旨味が溢れ出してしまう。 | Q4: =len(P4) -> 118 | R4: そのため、海中では常に出汁の香りが漂い、無数の魚たちが群がってくる。 出汁搾本人はこの体質に悩んでおり、「俺だって普通の海藻として静かに暮らしたいのに……」と嘆いているが、魚たちはお構いなしに周囲を泳ぎ回り、時にはその体をついばんでしまうことも。 | S4: =len(R4) -> 125 | T4: =len(W4) -> 130 | U4: 出汁搾を捕まえると、その村はしばらく食に困らなくなると言われているが、あまりに長く搾りすぎると、出汁が枯渇し、哀れな姿になってしまう。 そのため、村の者たちは一定の期間が過ぎると「もういいから海に帰れ」と海へ戻してやるのが習わしとなっていた。 | V4: =len(U4) -> 122 | W4: ある時、漁師たちはこの噂を聞きつけ、出汁搾を捕まえようとした。 しかし、捕まえてもなお出汁は止まらず、村中が絶品の味わいに包まれたため、結果として漁師たちは大いに喜んだという。 出汁搾自身は「やめろ……もう何も搾り取らないでくれ……」と涙を浮かべていたとか。 | X4: もし海で出汁の香りが漂ってきたら、それは出汁搾が近くにいる証拠かもしれない。 しかし、あまりに近づきすぎると、「お前も俺の出汁に引き寄せられたのか……」と悲しげな目で見つめられることになるだろう。 | Y4: =len(X4) -> 101 | AA4: =len(Z4) -> 0 | AC4: =len(AB4) -> 0
A5: 3 | B5: 膨風呂（ふくらぶろ） | C5: fukuraburo | D5: 宿場町の茶屋、銭湯の脱衣所、縁日の屋台街、酒場の路地裏 | E5: 膨風呂は、異常なほどお腹が膨れ上がった妖怪で、まるで風船のように浮きそうなほどの巨大な腹を持つ。 その一方で、腕や脚、顔は極端に細く、バランスが取れずにふわふわと漂うように動くことが多い。 膨れた腹は高く持ち上げたズボンと腹巻で覆われているが、その下には食べ物や小物、時には盗んだ品まで隠されているという。 この妖怪は主に 食い意地の張った人間や酒飲みの前に現れる。 屋台や宴席で「もう食べられない！」と言いながらも、まだ食べたそうにしている者の前に姿を現し、「その腹、まだ入るぞぉ～」と囁いてくる。 膨風呂の声を聞いてしまうと、不思議と食欲が湧き、限界を超えて食べたり飲んだりしてしまうという。 そして、その結果、本人の腹も膨れ上がり、しばらくの間、膨風呂のように膨張したまま動けなくなるといわれている。 また、膨風呂は盗み癖もあり、気に入った物をこっそり腹の中に隠してしまうことがある。 茶屋の菓子や酒、商人の小銭など、目を離した隙に消えてしまったら、もしかすると膨風呂の仕業かもしれない。 膨風呂に取り憑かれると、延々と食べ続けたり、身体が異様に膨らんでしまうことがある。 しかし、「満腹感を示す仕草」をすることで退散させることができる。 例えば、お腹をさすりながら「もう無理！」と大げさに言うと、膨風呂は「じゃあ仕方ないなぁ」と去っていくという。 また、腹巻の中には「赤い布」が嫌いという伝承があり、赤い手ぬぐいや帯を見せると驚いて逃げるとも言われている。 「食べすぎには気をつけろ」という教訓を伝える妖怪ともいわれ、節度を守れば害はない。 ただし、食い意地の張った者にはしつこく付きまとうため、大食いの者は要注意である。 | F5: ="【名】" & B5 & C5 &char(10) & "【番】" & text(A5,"0000") & char(10) &"【出現】"&D5& char(10)&"【特質】"& char(10)&E5&char(10)&char(10)&memo!$B$1 -> 【名】膨風呂（ふくらぶろ）fukuraburo 【番】0003 【出現】宿場町の茶屋、銭湯の脱衣所、縁日の屋台街、酒場の路地裏 【特質】 膨風呂は、異常なほどお腹が膨れ上がった妖怪で、まるで風船のように浮きそうなほどの巨大な腹を持つ。 その一方で、腕や脚、顔は極端に細く、バランスが取れずにふわふわと漂うように動くことが多い。 膨れた腹は高く持ち上げたズボンと腹巻で覆われているが、その下には食べ物や小物、時には盗んだ品まで隠されているという。 この妖怪は主に 食い意地の張った人間や酒飲みの前に現れる。 屋台や宴席で「もう食べられない！」と言いながらも、まだ食べたそうにしている者の前に姿を現し、「その腹、まだ入るぞぉ～」と囁いてくる。 膨風呂の声を聞いてしまうと、不思議と食欲が湧き、限界を超えて食べたり飲んだりしてしまうという。 そして、その結果、本人の腹も膨れ上がり、しばらくの間、膨風呂のように膨張したまま動けなくなるといわれている。 また、膨風呂は盗み癖もあり、気に入った物をこっそり腹の中に隠してしまうことがある。 茶屋の菓子や酒、商人の小銭など、目を離した隙に消えてしまったら、もしかすると膨風呂の仕業かもしれない。 膨風呂に取り憑かれると、延々と食べ続けたり、身体が異様に膨らんでしまうことがある。 しかし、「満腹感を示す仕草」をすることで退散させることができる。 例えば、お腹をさすりながら「もう無理！」と大げさに言うと、膨風呂は「じゃあ仕方ないなぁ」と去っていくという。 また、腹巻の中には「赤い布」が嫌いという伝承があり、赤い手ぬぐいや帯を見せると驚いて逃げるとも言われている。 「食べすぎには気をつけろ」という教訓を伝える妖怪ともいわれ、節度を守れば害はない。 ただし、食い意地の張った者にはしつこく付きまとうため、大食いの者は要注意である。 #妖怪 #yokai #sumie #monster #ghost | G5: 45694 | H5: 45696 | I5: ○ | J5: 45707 | K5: FLOW | L5: =len(E5) -> 744 | N5: =mid(F5,1,find("【特質】",F5)-1) &char(10)&memo!$B$2 -> 【名】膨風呂（ふくらぶろ）fukuraburo 【番】0003 【出現】宿場町の茶屋、銭湯の脱衣所、縁日の屋台街、酒場の路地裏 #妖怪 #お化け #怪物 #オリジナル妖怪 #monster #ghost #妖怪好き #浮世絵 #百鬼夜行 | O5: =len(N5) -> 119 | P5: 【特質】膨風呂は、異常なほどお腹が膨れ上がった妖怪で、まるで風船のように浮きそうなほどの巨大な腹を持つ。 その一方で、腕や脚、顔は極端に細く、バランスが取れずにふわふわと漂うように動くことが多い。 | Q5: =len(P5) -> 98 | R5: 膨れた腹は高く持ち上げたズボンと腹巻で覆われているが、その下には食べ物や小物、時には盗んだ品まで隠されているという。 この妖怪は主に 食い意地の張った人間や酒飲みの前に現れる。 | S5: =len(R5) -> 89 | T5: =len(W5) -> 114 | U5: そして、その結果、本人の腹も膨れ上がり、しばらくの間、膨風呂のように膨張したまま動けなくなるといわれている。 また、膨風呂は盗み癖もあり、気に入った物をこっそり腹の中に隠してしまうことがある。 | V5: =len(U5) -> 98 | W5: 屋台や宴席で「もう食べられない！」と言いながらも、まだ食べたそうにしている者の前に姿を現し、「その腹、まだ入るぞぉ～」と囁いてくる。 膨風呂の声を聞いてしまうと、不思議と食欲が湧き、限界を超えて食べたり飲んだりしてしまうという。 | X5: 茶屋の菓子や酒、商人の小銭など、目を離した隙に消えてしまったら、もしかすると膨風呂の仕業かもしれない。 膨風呂に取り憑かれると、延々と食べ続けたり、身体が異様に膨らんでしまうことがある。 | Y5: =len(X5) -> 95 | Z5: しかし「満腹感を示す仕草」をすることで退散させることができる。 例えば、お腹をさすりながら「もう無理！」と大げさに言うと、膨風呂は「じゃあ仕方ないなぁ」と去っていくという。 また、腹巻の中には「赤い布」が嫌いという伝承があり、赤い手ぬぐいや帯を見せると驚いて逃げるとも言われている | AA5: =len(Z5) -> 140 | AC5: =len(AB5) -> 0
A6: 4 | B6: 底視（そこみ） | C6: sokomi | D6: 書庫のある寺院、古書店、夜の寺子屋 | E6: 4cmもの厚さのびん底眼鏡をかけた妖怪。 その分厚いレンズの向こうにある目は、常人にはまともに見えず、覗き込んだ者は現実が歪んで見えるという。 横から見たときの異様な厚みが特徴で、そこには世の中の真理や禁忌の情報が刻まれているとも噂される。 彼が見つめた書物は、墨がにじんで読めなくなることがあり、学者や文人が恐れたという。 逆に、学びを深く求める者には「真実」を見せることもあるが、それは人間が知るにはあまりにも過酷なものであり、知ってしまった者は精神を病むか、異形となって闇に消えてしまうという。 かつて寺子屋で悪さをしていた子供が、彼の眼鏡に映った「何か」を見て以来、一切の悪戯をやめたという伝説も残されている。 | F6: ="【名】" & B6 & C6 &char(10) & "【番】" & text(A6,"0000") & char(10) &"【出現】"&D6& char(10)&"【特質】"& char(10)&E6&char(10)&char(10)&memo!$B$1 -> 【名】底視（そこみ）sokomi 【番】0004 【出現】書庫のある寺院、古書店、夜の寺子屋 【特質】 4cmもの厚さのびん底眼鏡をかけた妖怪。 その分厚いレンズの向こうにある目は、常人にはまともに見えず、覗き込んだ者は現実が歪んで見えるという。 横から見たときの異様な厚みが特徴で、そこには世の中の真理や禁忌の情報が刻まれているとも噂される。 彼が見つめた書物は、墨がにじんで読めなくなることがあり、学者や文人が恐れたという。 逆に、学びを深く求める者には「真実」を見せることもあるが、それは人間が知るにはあまりにも過酷なものであり、知ってしまった者は精神を病むか、異形となって闇に消えてしまうという。 かつて寺子屋で悪さをしていた子供が、彼の眼鏡に映った「何か」を見て以来、一切の悪戯をやめたという伝説も残されている。 #妖怪 #yokai #sumie #monster #ghost | G6: 45694 | H6: 45697 | I6: ○ | J6: 45710 | K6: Time Warp | L6: =len(E6) -> 312 | N6: =mid(F6,1,find("【特質】",F6)-1) &char(10)&memo!$B$2 -> 【名】底視（そこみ）sokomi 【番】0004 【出現】書庫のある寺院、古書店、夜の寺子屋 #妖怪 #お化け #怪物 #オリジナル妖怪 #monster #ghost #妖怪好き #浮世絵 #百鬼夜行 | O6: =len(N6) -> 102 | P6: 4cmもの厚さのびん底眼鏡をかけた妖怪。 その分厚いレンズの向こうにある目は、常人にはまともに見えず、覗き込んだ者は現実が歪んで見えるという。 横から見たときの異様な厚みが特徴で、そこには世の中の真理や禁忌の情報が刻まれているとも噂される。 | Q6: =len(P6) -> 120 | R6: 彼が見つめた書物は、墨がにじんで読めなくなることがあり、学者や文人が恐れたという。 逆に、学びを深く求める者には「真実」を見せることもあるが、それは人間が知るにはあまりにも過酷なものであり、知ってしまった者は精神を病むか、異形となって闇に消えてしまうという。 | S6: =len(R6) -> 129 | T6: =len(W6) -> 58 | V6: =len(U6) -> 0 | W6: かつて寺子屋で悪さをしていた子供が、彼の眼鏡に映った「何か」を見て以来、一切の悪戯をやめたという伝説も残されている。 | Y6: =len(X6) -> 0 | AA6: =len(Z6) -> 0 | AC6: =len(AB6) -> 0
A7: 5 | B7: 双喰鹿（そうしょくろく） | C7: soshokuroku | D7: 深い霧が立ち込める山間の湖や湿地帯 | E7: 一見すると鹿のような姿をしているが、首元には大きな裂け目があり、そこには魚のような生物が共生している。 この魚は鹿の体を住処とし、互いに共生しているが、鹿にとっては厄介な存在でもある。 普通の鹿の 2倍も腹が減るという欠点があり、その原因は 中の魚が極端な美食家だからである。 鹿は草食獣であるにも関わらず、魚のために狩りをしなければならず、時には小動物や鳥を捕まえることもある。 鹿と魚の共通の大好物は原木しいたけであり、原木しいたけの匂いを嗅ぐと、鹿も魚も異様に興奮する。 そのため原木しいたけを見つけたときが仕留める最大のチャンス。 興奮のあまり無防備になるため、狩人たちはこの瞬間を狙って仕留めることがある。 しかし、双喰鹿の肉は まったく食えたもんではない。 肉自体は硬くて臭く、内臓は魚のせいで独特の生臭さがある。 さらに、中の魚は 鹿が死ぬと最後の抵抗として飛び出し、食らいついてくる。 解体する際にも非常に厄介な妖怪として恐れられている。 この妖怪を見た者は、「あいつら、食い物のことで頭がいっぱいだ」と語るという…。 | F7: ="【名】" & B7 & C7 &char(10) & "【番】" & text(A7,"0000") & char(10) &"【出現】"&D7& char(10)&"【特質】"& char(10)&E7&char(10)&char(10)&memo!$B$1 -> 【名】双喰鹿（そうしょくろく）soshokuroku 【番】0005 【出現】深い霧が立ち込める山間の湖や湿地帯 【特質】 一見すると鹿のような姿をしているが、首元には大きな裂け目があり、そこには魚のような生物が共生している。 この魚は鹿の体を住処とし、互いに共生しているが、鹿にとっては厄介な存在でもある。 普通の鹿の 2倍も腹が減るという欠点があり、その原因は 中の魚が極端な美食家だからである。 鹿は草食獣であるにも関わらず、魚のために狩りをしなければならず、時には小動物や鳥を捕まえることもある。 鹿と魚の共通の大好物は原木しいたけであり、原木しいたけの匂いを嗅ぐと、鹿も魚も異様に興奮する。 そのため原木しいたけを見つけたときが仕留める最大のチャンス。 興奮のあまり無防備になるため、狩人たちはこの瞬間を狙って仕留めることがある。 しかし、双喰鹿の肉は まったく食えたもんではない。 肉自体は硬くて臭く、内臓は魚のせいで独特の生臭さがある。 さらに、中の魚は 鹿が死ぬと最後の抵抗として飛び出し、食らいついてくる。 解体する際にも非常に厄介な妖怪として恐れられている。 この妖怪を見た者は、「あいつら、食い物のことで頭がいっぱいだ」と語るという…。 #妖怪 #yokai #sumie #monster #ghost | G7: 45694 | H7: 45698 | I7: ○ | J7: - | L7: =len(E7) -> 473 | N7: =mid(F7,1,find("【特質】",F7)-1) &char(10)&memo!$B$2 -> 【名】双喰鹿（そうしょくろく）soshokuroku 【番】0005 【出現】深い霧が立ち込める山間の湖や湿地帯 #妖怪 #お化け #怪物 #オリジナル妖怪 #monster #ghost #妖怪好き #浮世絵 #百鬼夜行 | O7: =len(N7) -> 112 | P7: 一見すると鹿のような姿をしているが、首元には大きな裂け目があり、そこには魚のような生物が共生している。 この魚は鹿の体を住処とし、互いに共生しているが、鹿にとっては厄介な存在でもある。 | Q7: =len(P7) -> 93 | R7: 普通の鹿の 2倍も腹が減るという欠点があり、その原因は 中の魚が極端な美食家だからである。 鹿は草食獣であるにも関わらず、魚のために狩りをしなければならず、時には小動物や鳥を捕まえることもある。 | S7: =len(R7) -> 98 | T7: =len(W7) -> 117 | U7: しかし、双喰鹿の肉は まったく食えたもんではない。 肉自体は硬くて臭く、内臓は魚のせいで独特の生臭さがある。 さらに、中の魚は 鹿が死ぬと最後の抵抗として飛び出し、食らいついてくる。 解体する際にも非常に厄介な妖怪として恐れられている。 | V7: =len(U7) -> 119 | W7: 鹿と魚の共通の大好物は原木しいたけであり、原木しいたけの匂いを嗅ぐと、鹿も魚も異様に興奮する。 そのため原木しいたけを見つけたときが仕留める最大のチャンス。 興奮のあまり無防備になるため、狩人たちはこの瞬間を狙って仕留めることがある。 | X7: この妖怪を見た者は、「あいつら、食い物のことで頭がいっぱいだ」と語るという…。 | Y7: =len(X7) -> 39 | AA7: =len(Z7) -> 0 | AC7: =len(AB7) -> 0
A8: 6 | B8: 木魚童（もくぎょどう） | C8: mokugyodo | D8: 古い寺院、廃寺、荒れ果てた僧坊 | E8: かつて念仏僧たちが叩き続けた木魚が、人々の想いと煩悩を吸い込み、妖怪と化した姿。 その頭はまるで本物の木魚のように丸く彫られた木製の形をしており、体は童のように小さく、僧衣をまとっている。 昼間はただの木魚のように佇んでいるが、夜になると動き出し、静かに念仏を唱えながら寺の中を歩き回る。 木魚童は寺の修行僧を見守る存在であり、勤勉な者には穏やかに寄り添い、怠ける者にはその頭を差し出す。 「叩け」と促されるままに木魚を打つと、不思議なことに自らの煩悩が一つ抜け落ちたように感じるという。 しかし、あまりに多く打ち続けると、木魚童の身体は重く沈み込み、叩いた者の煩悩をすべて吸い取る代わりに、その者の心が空虚になってしまうと言われている。 また、木魚童のいる寺院では、夜になると誰もいない本堂から「ポク…ポク…」という木魚の音が聞こえてくることがある。 それは、僧たちの代わりに木魚童が自らの頭を叩き、寺に漂う煩悩を鎮めようとしているのかもしれない…。 | F8: ="【名】" & B8 & C8 &char(10) & "【番】" & text(A8,"0000") & char(10) &"【出現】"&D8& char(10)&"【特質】"& char(10)&E8&char(10)&char(10)&memo!$B$1 -> 【名】木魚童（もくぎょどう）mokugyodo 【番】0006 【出現】古い寺院、廃寺、荒れ果てた僧坊 【特質】 かつて念仏僧たちが叩き続けた木魚が、人々の想いと煩悩を吸い込み、妖怪と化した姿。 その頭はまるで本物の木魚のように丸く彫られた木製の形をしており、体は童のように小さく、僧衣をまとっている。 昼間はただの木魚のように佇んでいるが、夜になると動き出し、静かに念仏を唱えながら寺の中を歩き回る。 木魚童は寺の修行僧を見守る存在であり、勤勉な者には穏やかに寄り添い、怠ける者にはその頭を差し出す。 「叩け」と促されるままに木魚を打つと、不思議なことに自らの煩悩が一つ抜け落ちたように感じるという。 しかし、あまりに多く打ち続けると、木魚童の身体は重く沈み込み、叩いた者の煩悩をすべて吸い取る代わりに、その者の心が空虚になってしまうと言われている。 また、木魚童のいる寺院では、夜になると誰もいない本堂から「ポク…ポク…」という木魚の音が聞こえてくることがある。 それは、僧たちの代わりに木魚童が自らの頭を叩き、寺に漂う煩悩を鎮めようとしているのかもしれない…。 #妖怪 #yokai #sumie #monster #ghost | G8: 45694 | H8: 45699 | I8: ○ | J8: 45714 | K8: さよならプラスティックワールド | L8: =len(E8) -> 430 | N8: =mid(F8,1,find("【特質】",F8)-1) &char(10)&memo!$B$2 -> 【名】木魚童（もくぎょどう）mokugyodo 【番】0006 【出現】古い寺院、廃寺、荒れ果てた僧坊 #妖怪 #お化け #怪物 #オリジナル妖怪 #monster #ghost #妖怪好き #浮世絵 #百鬼夜行 | O8: =len(N8) -> 107 | P8: かつて念仏僧たちが叩き続けた木魚が、人々の想いと煩悩を吸い込み、妖怪と化した姿。 その頭はまるで本物の木魚のように丸く彫られた木製の形をしており、体は童のように小さく、僧衣をまとっている。 | Q8: =len(P8) -> 95 | R8: 昼間はただの木魚のように佇んでいるが、夜になると動き出し、静かに念仏を唱えながら寺の中を歩き回る。 木魚童は寺の修行僧を見守る存在であり、勤勉な者には穏やかに寄り添い、怠ける者にはその頭を差し出す。 | S8: =len(R8) -> 101 | T8: =len(W8) -> 124 | U8: また、木魚童のいる寺院では、夜になると誰もいない本堂から「ポク…ポク…」という木魚の音が聞こえてくることがある。 それは、僧たちの代わりに木魚童が自らの頭を叩き、寺に漂う煩悩を鎮めようとしているのかもしれない…。 | V8: =len(U8) -> 106 | W8: 「叩け」と促されるままに木魚を打つと、不思議なことに自らの煩悩が一つ抜け落ちたように感じるという。 しかし、あまりに多く打ち続けると、木魚童の身体は重く沈み込み、叩いた者の煩悩をすべて吸い取る代わりに、その者の心が空虚になってしまうと言われている。 | Y8: =len(X8) -> 0 | AA8: =len(Z8) -> 0 | AC8: =len(AB8) -> 0
A9: 7 | B9: 鞍憑（くらつき） | C9: kuratsuki | D9: 古い馬宿、廃れた街道、戦場跡 | E9: かつて名のある武士や馬乗りが使っていた鞍が、持ち主を失い、長年放置された末に妖怪化したもの。 明治後期から昭和初期にかけてはサドルおばけとも呼ばれる。 一見、古びた鞍に見えるが、夜になると音もなく宙を漂い、かつての主を求めて彷徨う。 人が近づくと鞍の底から黒い霧のような手が伸び、無理やり背に乗せようとする。 乗ってしまった者は鞍に縛りつけられ、馬もないのに走り続けなければならない。 伝説によれば、鞍憑に取り憑かれた者は次第に体力を奪われ、やがて魂を乗っ取られてしまうという。 唯一の対処法は、かつての持ち主の名を唱え、敬意を示すこと。 その名を聞くと、鞍憑はしばし動きを止めるが、完全に消え去ることはない。 特に戦場跡や旧街道に現れることが多く、夜道を行く者は決して捨てられた鞍を背負わぬよう注意せねばならない…。 | F9: ="【名】" & B9 & C9 &char(10) & "【番】" & text(A9,"0000") & char(10) &"【出現】"&D9& char(10)&"【特質】"& char(10)&E9&char(10)&char(10)&memo!$B$1 -> 【名】鞍憑（くらつき）kuratsuki 【番】0007 【出現】古い馬宿、廃れた街道、戦場跡 【特質】 かつて名のある武士や馬乗りが使っていた鞍が、持ち主を失い、長年放置された末に妖怪化したもの。 明治後期から昭和初期にかけてはサドルおばけとも呼ばれる。 一見、古びた鞍に見えるが、夜になると音もなく宙を漂い、かつての主を求めて彷徨う。 人が近づくと鞍の底から黒い霧のような手が伸び、無理やり背に乗せようとする。 乗ってしまった者は鞍に縛りつけられ、馬もないのに走り続けなければならない。 伝説によれば、鞍憑に取り憑かれた者は次第に体力を奪われ、やがて魂を乗っ取られてしまうという。 唯一の対処法は、かつての持ち主の名を唱え、敬意を示すこと。 その名を聞くと、鞍憑はしばし動きを止めるが、完全に消え去ることはない。 特に戦場跡や旧街道に現れることが多く、夜道を行く者は決して捨てられた鞍を背負わぬよう注意せねばならない…。 #妖怪 #yokai #sumie #monster #ghost | G9: 45694 | H9: 45700 | I9: ○ | J9: 45717 | K9: 電造人間 | L9: =len(E9) -> 362 | N9: =mid(F9,1,find("【特質】",F9)-1) &char(10)&memo!$B$2 -> 【名】鞍憑（くらつき）kuratsuki 【番】0007 【出現】古い馬宿、廃れた街道、戦場跡 #妖怪 #お化け #怪物 #オリジナル妖怪 #monster #ghost #妖怪好き #浮世絵 #百鬼夜行 | O9: =len(N9) -> 103 | P9: かつて名のある武士や馬乗りが使っていた鞍が、持ち主を失い、長年放置された末に妖怪化したもの。 明治後期から昭和初期にかけてはサドルおばけとも呼ばれる。 一見、古びた鞍に見えるが、夜になると音もなく宙を漂い、かつての主を求めて彷徨う。 | Q9: =len(P9) -> 117 | R9: 人が近づくと鞍の底から黒い霧のような手が伸び、無理やり背に乗せようとする。 乗ってしまった者は鞍に縛りつけられ、馬もないのに走り続けなければならない。 伝説によれば、鞍憑に取り憑かれた者は次第に体力を奪われ、やがて魂を乗っ取られてしまうという。 | S9: =len(R9) -> 124 | T9: =len(W9) -> 119 | V9: =len(U9) -> 0 | W9: 唯一の対処法は、かつての持ち主の名を唱え、敬意を示すこと。 その名を聞くと、鞍憑はしばし動きを止めるが、完全に消え去ることはない。 特に戦場跡や旧街道に現れることが多く、夜道を行く者は決して捨てられた鞍を背負わぬよう注意せねばならない…。 | Y9: =len(X9) -> 0 | AA9: =len(Z9) -> 0 | AC9: =len(AB9) -> 0
A10: 8 | B10: 卵童（らんどう） | C10: rando | D10: 町の食料品店、家庭の台所 | E10: 普通の卵に紛れ込むことを得意とする妖怪。 昭和初期、紙の卵パックが使われるようになった頃から、人間の目を欺きやすくなったとされる。 見た目は完全に普通の卵だが、じっと見つめると他の卵とは微妙に違う顔つきが浮かび上がることがある。 調理されることを極端に嫌がり、割られそうになるとヒビの間からぎょろりとした目が覗き、時には小さく「やめろ…」とつぶやくこともある。最も厄介なのは、誤って茹でて食べてしまった場合である。 卵童を食べた者は、無性にプロレス漫画を描きたくなる。 しかも、突然インスピレーションが湧き、朝から晩まで筋骨隆々のレスラーたちが闘う姿を描き続けてしまう。 筆を止めることができず、気づけば何十冊ものネームが出来上がることもあるが、不思議なことに、その漫画は決して完成しない。 どれだけ描いても、最後の試合の決着だけはどうしても描けず、最終話のページが永遠に白紙のままになるという。 この現象は「卵童の呪い」と呼ばれ、昭和の漫画家たちの間では「卵はよく見て買え」と語り継がれたという。 しかし、現代でもこの妖怪が紛れ込んでいるかどうかは不明であり、もし最近、無性にプロレス漫画を描きたくなったのなら…あなたの朝食のゆで卵に、何かが潜んでいたのかもしれない。 | F10: ="【名】" & B10 & C10 &char(10) & "【番】" & text(A10,"0000") & char(10) &"【出現】"&D10& char(10)&"【特質】"& char(10)&E10&char(10)&char(10)&memo!$B$1 -> 【名】卵童（らんどう）rando 【番】0008 【出現】町の食料品店、家庭の台所 【特質】 普通の卵に紛れ込むことを得意とする妖怪。 昭和初期、紙の卵パックが使われるようになった頃から、人間の目を欺きやすくなったとされる。 見た目は完全に普通の卵だが、じっと見つめると他の卵とは微妙に違う顔つきが浮かび上がることがある。 調理されることを極端に嫌がり、割られそうになるとヒビの間からぎょろりとした目が覗き、時には小さく「やめろ…」とつぶやくこともある。最も厄介なのは、誤って茹でて食べてしまった場合である。 卵童を食べた者は、無性にプロレス漫画を描きたくなる。 しかも、突然インスピレーションが湧き、朝から晩まで筋骨隆々のレスラーたちが闘う姿を描き続けてしまう。 筆を止めることができず、気づけば何十冊ものネームが出来上がることもあるが、不思議なことに、その漫画は決して完成しない。 どれだけ描いても、最後の試合の決着だけはどうしても描けず、最終話のページが永遠に白紙のままになるという。 この現象は「卵童の呪い」と呼ばれ、昭和の漫画家たちの間では「卵はよく見て買え」と語り継がれたという。 しかし、現代でもこの妖怪が紛れ込んでいるかどうかは不明であり、もし最近、無性にプロレス漫画を描きたくなったのなら…あなたの朝食のゆで卵に、何かが潜んでいたのかもしれない。 #妖怪 #yokai #sumie #monster #ghost | G10: 45694 | H10: 45701 | I10: ○ | J10: 45721 | K10: FUSION | L10: =len(E10) -> 541 | N10: =mid(F10,1,find("【特質】",F10)-1) &char(10)&memo!$B$2 -> 【名】卵童（らんどう）rando 【番】0008 【出現】町の食料品店、家庭の台所 #妖怪 #お化け #怪物 #オリジナル妖怪 #monster #ghost #妖怪好き #浮世絵 #百鬼夜行 | O10: =len(N10) -> 97 | P10: 普通の卵に紛れ込むことを得意とする妖怪。 昭和初期、紙の卵パックが使われるようになった頃から、人間の目を欺きやすくなったとされる。 見た目は完全に普通の卵だが、じっと見つめると他の卵とは微妙に違う顔つきが浮かび上がることがある。 | Q10: =len(P10) -> 114 | R10: 調理されることを極端に嫌がり、割られそうになるとヒビの間からぎょろりとした目が覗き、時には小さく「やめろ…」とつぶやくこともある。最も厄介なのは、誤って茹でて食べてしまった場合である。 卵童を食べた者は、無性にプロレス漫画を描きたくなる。 | S10: =len(R10) -> 121 | T10: =len(W10) -> 110 | U10: どれだけ描いても、最後の試合の決着だけはどうしても描けず、最終話のページが永遠に白紙のままになるという。 この現象は「卵童の呪い」と呼ばれ、昭和の漫画家たちの間では「卵はよく見て買え」と語り継がれたという。 | V10: =len(U10) -> 105 | W10: しかも、突然インスピレーションが湧き、朝から晩まで筋骨隆々のレスラーたちが闘う姿を描き続けてしまう。 筆を止めることができず、気づけば何十冊ものネームが出来上がることもあるが、不思議なことに、その漫画は決して完成しない。 | X10: しかし、現代でもこの妖怪が紛れ込んでいるかどうかは不明であり、もし最近、無性にプロレス漫画を描きたくなったのなら…あなたの朝食のゆで卵に、何かが潜んでいたのかもしれない。 | Y10: =len(X10) -> 86 | AA10: =len(Z10) -> 0 | AC10: =len(AB10) -> 0
A11: 9 | B11: 沈架響橋（ちんかきょうきょう） | C11: chinkakyokyo | D11: 人里離れた川辺、寂れた渡し場 | E11: 昔の桟橋の化身とも言われる妖怪。 全身を伸ばして川をまたぎ、人が安全に渡れるように橋となる。 しかし、ただの橋ではなく、特定の者にのみ反応を示すという。 絶世の美女が渡ると、沈架響橋の体はたちまち波打ち、興奮するかのように大きくうねり始める。 渡る者にとっては危険極まりないが、それはすなわち沈架響橋に認められた証であり、誉れでもあるとされる。 その昔、幾多の名だたる美女が試しに渡り、沈架響橋のたわむ姿を見て己の美しさを誇ったという。 しかし、ある日、ある高飛車な娘が 「私が渡れば当然波打つだろう」と意気揚々と橋を踏みしめたが、沈架響橋は微動だにしなかった。 それどころか、まるで石のように冷え切り、静まり返っていたという。 羞恥に震えた娘は誰にもそのことを言わぬまま、橋を渡りきったが、それ以降の消息は知れない。 沈架響橋が何を基準に「反応する者」と「しない者」を選んでいるのかは誰にもわからない。 外見の美だけではなく、内面を見透かしているのではないかとも噂されている。 今もどこかの川辺で、夜ごと橋となり、渡る者を試しているのかもしれない。 | F11: ="【名】" & B11 & C11 &char(10) & "【番】" & text(A11,"0000") & char(10) &"【出現】"&D11& char(10)&"【特質】"& char(10)&E11&char(10)&char(10)&memo!$B$1 -> 【名】沈架響橋（ちんかきょうきょう）chinkakyokyo 【番】0009 【出現】人里離れた川辺、寂れた渡し場 【特質】 昔の桟橋の化身とも言われる妖怪。 全身を伸ばして川をまたぎ、人が安全に渡れるように橋となる。 しかし、ただの橋ではなく、特定の者にのみ反応を示すという。 絶世の美女が渡ると、沈架響橋の体はたちまち波打ち、興奮するかのように大きくうねり始める。 渡る者にとっては危険極まりないが、それはすなわち沈架響橋に認められた証であり、誉れでもあるとされる。 その昔、幾多の名だたる美女が試しに渡り、沈架響橋のたわむ姿を見て己の美しさを誇ったという。 しかし、ある日、ある高飛車な娘が 「私が渡れば当然波打つだろう」と意気揚々と橋を踏みしめたが、沈架響橋は微動だにしなかった。 それどころか、まるで石のように冷え切り、静まり返っていたという。 羞恥に震えた娘は誰にもそのことを言わぬまま、橋を渡りきったが、それ以降の消息は知れない。 沈架響橋が何を基準に「反応する者」と「しない者」を選んでいるのかは誰にもわからない。 外見の美だけではなく、内面を見透かしているのではないかとも噂されている。 今もどこかの川辺で、夜ごと橋となり、渡る者を試しているのかもしれない。 #妖怪 #yokai #sumie #monster #ghost | G11: 45694 | H11: 45702 | I11: ○ | J11: - | L11: =len(E11) -> 478 | N11: =mid(F11,1,find("【特質】",F11)-1) &char(10)&memo!$B$2 -> 【名】沈架響橋（ちんかきょうきょう）chinkakyokyo 【番】0009 【出現】人里離れた川辺、寂れた渡し場 #妖怪 #お化け #怪物 #オリジナル妖怪 #monster #ghost #妖怪好き #浮世絵 #百鬼夜行 | O11: =len(N11) -> 113 | P11: 昔の桟橋の化身とも言われる妖怪。 全身を伸ばして川をまたぎ、人が安全に渡れるように橋となる。 しかし、ただの橋ではなく、特定の者にのみ反応を示すという。 絶世の美女が渡ると、沈架響橋の体はたちまち波打ち、興奮するかのように大きくうねり始める。 | Q11: =len(P11) -> 123 | R11: 渡る者にとっては危険極まりないが、それはすなわち沈架響橋に認められた証であり、誉れでもあるとされる。 その昔、幾多の名だたる美女が試しに渡り、沈架響橋のたわむ姿を見て己の美しさを誇ったという。 | S11: =len(R11) -> 96 | T11: =len(W11) -> 140 | U11: 沈架響橋が何を基準に「反応する者」と「しない者」を選んでいるのかは誰にもわからない。 外見の美だけではなく、内面を見透かしているのではないかとも噂されている。 今もどこかの川辺で、夜ごと橋となり、渡る者を試しているのかもしれない。 | V11: =len(U11) -> 115 | W11: しかし、ある日、ある高飛車な娘が 「私が渡れば当然波打つだろう」と意気揚々と橋を踏みしめたが、沈架響橋は微動だにしなかった。 それどころか、まるで石のように冷え切り、静まり返っていたという。 羞恥に震えた娘は誰にもそのことを言わぬまま、橋を渡りきったが、それ以降の消息は知れない。 | Y11: =len(X11) -> 0 | AA11: =len(Z11) -> 0 | AC11: =len(AB11) -> 0
A12: 10 | B12: 氷砲凍鵺（ひょうほういてぬえ） | C12: hyohoitenue | D12: 極寒の海岸、流氷の上、密漁者が跋扈する漁場 | E12: 氷砲凍鵺は、かつて密漁者によって仲間たちが無残に乱獲されたことに怒り、怨念と復讐心から誕生した妖怪である。 純白のペンギンの姿をしているが、その腹部から長く鋭い銃口が生え、妖しげな霧を纏っている。 この妖怪の最大の特徴は、その弾丸。 密漁者に命を奪われたセイウチの巨大な前歯を拾い集め、霊的な力を込めてライフルへ装填する。 放たれた牙は空を裂き、氷の槍のごとく標的を貫く。 撃たれた者は凍りつき、やがて氷の塊と化して大海へ沈んでいくと伝えられる。 密漁者の間では、吹雪の中で「視線を感じたらもう遅い」と恐れられており、ある者は視界の端に白い影を捉えた瞬間に命を奪われたという。 標的が海に還るたび、氷砲凍鵺は低く鳴き、凍てつく海風にその声が響くのだ。 密漁を行わない者には害を及ぼさず、むしろ遭難した者や正当な漁師には道を示すとも言われている。 しかし、それも全ては「復讐が果たされるまでの間」なのかもしれない。 | F12: ="【名】" & B12 & C12 &char(10) & "【番】" & text(A12,"0000") & char(10) &"【出現】"&D12& char(10)&"【特質】"& char(10)&E12&char(10)&char(10)&memo!$B$1 -> 【名】氷砲凍鵺（ひょうほういてぬえ）hyohoitenue 【番】0010 【出現】極寒の海岸、流氷の上、密漁者が跋扈する漁場 【特質】 氷砲凍鵺は、かつて密漁者によって仲間たちが無残に乱獲されたことに怒り、怨念と復讐心から誕生した妖怪である。 純白のペンギンの姿をしているが、その腹部から長く鋭い銃口が生え、妖しげな霧を纏っている。 この妖怪の最大の特徴は、その弾丸。 密漁者に命を奪われたセイウチの巨大な前歯を拾い集め、霊的な力を込めてライフルへ装填する。 放たれた牙は空を裂き、氷の槍のごとく標的を貫く。 撃たれた者は凍りつき、やがて氷の塊と化して大海へ沈んでいくと伝えられる。 密漁者の間では、吹雪の中で「視線を感じたらもう遅い」と恐れられており、ある者は視界の端に白い影を捉えた瞬間に命を奪われたという。 標的が海に還るたび、氷砲凍鵺は低く鳴き、凍てつく海風にその声が響くのだ。 密漁を行わない者には害を及ぼさず、むしろ遭難した者や正当な漁師には道を示すとも言われている。 しかし、それも全ては「復讐が果たされるまでの間」なのかもしれない。 #妖怪 #yokai #sumie #monster #ghost | G12: 45694 | H12: 45703 | I12: ○ | J12: 45724 | K12: MOON | L12: =len(E12) -> 409 | N12: =mid(F12,1,find("【特質】",F12)-1) &char(10)&memo!$B$2 -> 【名】氷砲凍鵺（ひょうほういてぬえ）hyohoitenue 【番】0010 【出現】極寒の海岸、流氷の上、密漁者が跋扈する漁場 #妖怪 #お化け #怪物 #オリジナル妖怪 #monster #ghost #妖怪好き #浮世絵 #百鬼夜行 | O12: =len(N12) -> 119 | P12: 【特質】氷砲凍鵺は、かつて密漁者によって仲間たちが無残に乱獲されたことに怒り、怨念と復讐心から誕生した妖怪である。 純白のペンギンの姿をしているが、その腹部から長く鋭い銃口が生え、妖しげな霧を纏っている。 この妖怪の最大の特徴は、その弾丸。 | Q12: =len(P12) -> 120 | R12: 密漁者に命を奪われたセイウチの巨大な前歯を拾い集め、霊的な力を込めてライフルへ装填する。 放たれた牙は空を裂き、氷の槍のごとく標的を貫く。 撃たれた者は凍りつき、やがて氷の塊と化して大海へ沈んでいくと伝えられる。 | S12: =len(R12) -> 106 | T12: =len(W12) -> 101 | U12: 密漁を行わない者には害を及ぼさず、むしろ遭難した者や正当な漁師には道を示すとも言われている。 しかし、それも全ては「復讐が果たされるまでの間」なのかもしれない。 | V12: =len(U12) -> 80 | W12: 密漁者の間では、吹雪の中で「視線を感じたらもう遅い」と恐れられており、ある者は視界の端に白い影を捉えた瞬間に命を奪われたという。 標的が海に還るたび、氷砲凍鵺は低く鳴き、凍てつく海風にその声が響くのだ。 | Y12: =len(X12) -> 0 | AA12: =len(Z12) -> 0 | AC12: =len(AB12) -> 0
A13: 11 | B13: 髪哭婆（かみなきば） | C13: kaminakiba | D13: 人里離れた山間の村、寂れた古寺の近く、あるいは廃れた婚礼場跡 | E13: 推定700歳の妖怪であり、かつては人間の女性だったという。 愛する夫と幸せに生き、彼を最期まで看取った後、「次もこの幸せを享受したい」と強く願ったことが妖力を生み、妖怪へと変化した。 彼女の外見は、痩せ細った老婆の姿だが、髪は黒々と豊かで異様に長く、頭上で大きなハート型に結われている。 この髪は自在に動き、時に触手のように伸びて若者を捕らえる。 髪哭婆は「次の夫」を探しており、若人を見つけると優しく微笑みながら攫い、自らの住処へ連れ帰る。 そして、手厚くもてなし、愛情深く世話をする。 食事は豪華で、寝床もふかふか。 しかし、一つだけ絶対にこなさねばならない「試練」がある。 試練とは「ハートの輪くぐり」である。 毎晩、若人は髪哭婆が作った巨大なハート型の輪をくぐらなければならない。 一見、簡単そうに思えるが、この輪は意思を持ち、サイズを変えたり、動き回ったり、突然閉じたりするため、決して容易ではない。 若人が失敗すれば、髪哭婆はしばらく悲しみ、やがて新たな「幸せの相手」を探しに行く。 この試練を長く耐え抜いた者もいるが、多くの若人は「毎晩これを続けるのは無理だ」と悟り、最終的に逃げ出そうとする。 だが、髪哭婆は意外にも追いかけてはこない。 「愛に飽きたのね…仕方ないわねぇ…」と寂しげに微笑み、そっと見送るという。 ただし、逃げ出してから数日経ったあとの若人は、日常に退屈し始める。何もやる気が出ない。 無気力となり、果ては自ら命を絶つものが続出したという。 最近の若人が写真を撮るときにハートマークを作るのは、髪哭婆への哀悼を示す追憶のポーズなのかもしれない。 | F13: ="【名】" & B13 & C13 &char(10) & "【番】" & text(A13,"0000") & char(10) &"【出現】"&D13& char(10)&"【特質】"& char(10)&E13&char(10)&char(10)&memo!$B$1 -> 【名】髪哭婆（かみなきば）kaminakiba 【番】0011 【出現】人里離れた山間の村、寂れた古寺の近く、あるいは廃れた婚礼場跡 【特質】 推定700歳の妖怪であり、かつては人間の女性だったという。 愛する夫と幸せに生き、彼を最期まで看取った後、「次もこの幸せを享受したい」と強く願ったことが妖力を生み、妖怪へと変化した。 彼女の外見は、痩せ細った老婆の姿だが、髪は黒々と豊かで異様に長く、頭上で大きなハート型に結われている。 この髪は自在に動き、時に触手のように伸びて若者を捕らえる。 髪哭婆は「次の夫」を探しており、若人を見つけると優しく微笑みながら攫い、自らの住処へ連れ帰る。 そして、手厚くもてなし、愛情深く世話をする。 食事は豪華で、寝床もふかふか。 しかし、一つだけ絶対にこなさねばならない「試練」がある。 試練とは「ハートの輪くぐり」である。 毎晩、若人は髪哭婆が作った巨大なハート型の輪をくぐらなければならない。 一見、簡単そうに思えるが、この輪は意思を持ち、サイズを変えたり、動き回ったり、突然閉じたりするため、決して容易ではない。 若人が失敗すれば、髪哭婆はしばらく悲しみ、やがて新たな「幸せの相手」を探しに行く。 この試練を長く耐え抜いた者もいるが、多くの若人は「毎晩これを続けるのは無理だ」と悟り、最終的に逃げ出そうとする。 だが、髪哭婆は意外にも追いかけてはこない。 「愛に飽きたのね…仕方ないわねぇ…」と寂しげに微笑み、そっと見送るという。 ただし、逃げ出してから数日経ったあとの若人は、日常に退屈し始める。何もやる気が出ない。 無気力となり、果ては自ら命を絶つものが続出したという。 最近の若人が写真を撮るときにハートマークを作るのは、髪哭婆への哀悼を示す追憶のポーズなのかもしれない。 #妖怪 #yokai #sumie #monster #ghost | G13: 45694 | H13: 45704 | I13: ○ | J13: 45728 | K13: I still love U | L13: =len(E13) -> 695 | N13: =mid(F13,1,find("【特質】",F13)-1) &char(10)&memo!$B$2 -> 【名】髪哭婆（かみなきば）kaminakiba 【番】0011 【出現】人里離れた山間の村、寂れた古寺の近く、あるいは廃れた婚礼場跡 #妖怪 #お化け #怪物 #オリジナル妖怪 #monster #ghost #妖怪好き #浮世絵 #百鬼夜行 | O13: =len(N13) -> 122 | P13: 【特質】推定700歳の妖怪であり、かつては人間の女性だったという。 愛する夫と幸せに生き、彼を最期まで看取った後、「次もこの幸せを享受したい」と強く願ったことが妖力を生み、妖怪へと変化した。 | Q13: =len(P13) -> 95 | R13: 彼女の外見は、痩せ細った老婆の姿だが、髪は黒々と豊かで異様に長く、頭上で大きなハート型に結われている。 この髪は自在に動き、時に触手のように伸びて若者を捕らえる。 髪哭婆は「次の夫」を探しており、若人を見つけると優しく微笑みながら攫い、自らの住処へ連れ帰る。 | S13: =len(R13) -> 130 | T13: =len(W13) -> 123 | U13: 一見、簡単そうに思えるが、この輪は意思を持ち、サイズを変えたり、動き回ったり、突然閉じたりするため、決して容易ではない。 若人が失敗すれば、髪哭婆はしばらく悲しみ、やがて新たな「幸せの相手」を探しに行く。 | V13: =len(U13) -> 102 | W13: そして、手厚くもてなし、愛情深く世話をする。 食事は豪華で、寝床もふかふか。 しかし、一つだけ絶対にこなさねばならない「試練」がある。 試練とは「ハートの輪くぐり」である。 毎晩、若人は髪哭婆が作った巨大なハート型の輪をくぐらなければならない。 | X13: この試練を長く耐え抜いた者もいるが、多くの若人は「毎晩これを続けるのは無理だ」と悟り、最終的に逃げ出そうとする。 だが、髪哭婆は意外にも追いかけてはこない。 「愛に飽きたのね…仕方ないわねぇ…」と寂しげに微笑み、そっと見送るという。 | Y13: =len(X13) -> 117 | Z13: ただし、逃げ出してから数日経ったあとの若人は、日常に退屈し始める。何もやる気が出ない。 無気力となり、果ては自ら命を絶つものが続出したという。 最近の若人が写真を撮るときにハートマークを作るのは、髪哭婆への哀悼を示す追憶のポーズなのかもしれない。 | AA13: =len(Z13) -> 124 | AC13: =len(AB13) -> 0
A14: 12 | B14: 餡幽鬼（あんゆうき） | C14: anyuki | D14: 田舎の古い民家、仏壇のある座敷、秋の彼岸の夜 | E14: その昔、一匹の忠犬がおはぎへの強い恨みを抱いたまま妖怪と化した存在。 主人がおはぎを喉に詰まらせて亡くなった際、「これが主人を殺した」と思い込み、怨念を募らせた。 その思いが昇華されず、「餡幽鬼」となった。 その姿は、かすれた墨のように揺らめく犬の影。 おはぎを憎み、供え物を吹き飛ばしたり、甘い香りをかき消そうとする。 しかし、誰かが幸せそうにおはぎを食べる姿を見ると、心が揺れる。 特に、ある老人が嬉しそうに頬張る様子を見た時、「おはぎに罪はないのかもしれない」と葛藤するが、完全には恨みを捨てきれない。 ある村では、おはぎを供える際に犬用の供え物も一緒に置く習慣がある。 それは、迷える餡幽鬼が少しでも安らげるようにとの願いから始まったという。 | F14: ="【名】" & B14 & C14 &char(10) & "【番】" & text(A14,"0000") & char(10) &"【出現】"&D14& char(10)&"【特質】"& char(10)&E14&char(10)&char(10)&memo!$B$1 -> 【名】餡幽鬼（あんゆうき）anyuki 【番】0012 【出現】田舎の古い民家、仏壇のある座敷、秋の彼岸の夜 【特質】 その昔、一匹の忠犬がおはぎへの強い恨みを抱いたまま妖怪と化した存在。 主人がおはぎを喉に詰まらせて亡くなった際、「これが主人を殺した」と思い込み、怨念を募らせた。 その思いが昇華されず、「餡幽鬼」となった。 その姿は、かすれた墨のように揺らめく犬の影。 おはぎを憎み、供え物を吹き飛ばしたり、甘い香りをかき消そうとする。 しかし、誰かが幸せそうにおはぎを食べる姿を見ると、心が揺れる。 特に、ある老人が嬉しそうに頬張る様子を見た時、「おはぎに罪はないのかもしれない」と葛藤するが、完全には恨みを捨てきれない。 ある村では、おはぎを供える際に犬用の供え物も一緒に置く習慣がある。 それは、迷える餡幽鬼が少しでも安らげるようにとの願いから始まったという。 #妖怪 #yokai #sumie #monster #ghost | G14: 45694 | H14: 45705 | I14: ○ | J14: - | L14: =len(E14) -> 327 | N14: =mid(F14,1,find("【特質】",F14)-1) &char(10)&memo!$B$2 -> 【名】餡幽鬼（あんゆうき）anyuki 【番】0012 【出現】田舎の古い民家、仏壇のある座敷、秋の彼岸の夜 #妖怪 #お化け #怪物 #オリジナル妖怪 #monster #ghost #妖怪好き #浮世絵 #百鬼夜行 | O14: =len(N14) -> 110 | P14: 【特質】その昔、一匹の忠犬がおはぎへの強い恨みを抱いたまま妖怪と化した存在。 主人がおはぎを喉に詰まらせて亡くなった際、「これが主人を殺した」と思い込み、怨念を募らせた。 その思いが昇華されず、「餡幽鬼」となった。 | Q14: =len(P14) -> 107 | R14: その姿は、かすれた墨のように揺らめく犬の影。 おはぎを憎み、供え物を吹き飛ばしたり、甘い香りをかき消そうとする。 しかし、誰かが幸せそうにおはぎを食べる姿を見ると、心が揺れる。 | S14: =len(R14) -> 88 | T14: =len(W14) -> 133 | V14: =len(U14) -> 0 | W14: 特に、ある老人が嬉しそうに頬張る様子を見た時、「おはぎに罪はないのかもしれない」と葛藤するが、完全には恨みを捨てきれない。 ある村では、おはぎを供える際に犬用の供え物も一緒に置く習慣がある。 それは、迷える餡幽鬼が少しでも安らげるようにとの願いから始まったという。 | Y14: =len(X14) -> 0 | AA14: =len(Z14) -> 0 | AC14: =len(AB14) -> 0
A15: 13 | B15: 塵鬼囃（じんきばやし） | C15: jinkibayashi | D15: 子供の家や庭、学校の裏庭、神社の境内 | E15: その昔、東北のある地方では10歳で成人を迎えるとされていた。 塵鬼囃は人間が10歳の誕生日を迎えた夜、それまでについた嘘の数だけ現れ、人間の周りを取り囲む。 塵ほどに小さな妖怪たちはかすかな声でに「嘘ついたね」「ほんとうのことを話そうよ」と囁く。 しかし嘘の数が多いほど、声は大きく、くすくすと笑う音や祭囃子のような不気味な音が混ざることもあるという。 塵鬼囃は、子供が嘘をすべて認めれば、その夜のうちに消える。 だが、一つでも隠したままだと、最後にこう囁いて去る。 「また来年、お祝いに来るね。」 ただし、翌年の誕生日を迎えることは、決してなかったと言われている。 | F15: ="【名】" & B15 & C15 &char(10) & "【番】" & text(A15,"0000") & char(10) &"【出現】"&D15& char(10)&"【特質】"& char(10)&E15&char(10)&char(10)&memo!$B$1 -> 【名】塵鬼囃（じんきばやし）jinkibayashi 【番】0013 【出現】子供の家や庭、学校の裏庭、神社の境内 【特質】 その昔、東北のある地方では10歳で成人を迎えるとされていた。 塵鬼囃は人間が10歳の誕生日を迎えた夜、それまでについた嘘の数だけ現れ、人間の周りを取り囲む。 塵ほどに小さな妖怪たちはかすかな声でに「嘘ついたね」「ほんとうのことを話そうよ」と囁く。 しかし嘘の数が多いほど、声は大きく、くすくすと笑う音や祭囃子のような不気味な音が混ざることもあるという。 塵鬼囃は、子供が嘘をすべて認めれば、その夜のうちに消える。 だが、一つでも隠したままだと、最後にこう囁いて去る。 「また来年、お祝いに来るね。」 ただし、翌年の誕生日を迎えることは、決してなかったと言われている。 #妖怪 #yokai #sumie #monster #ghost | G15: 45694 | H15: 45706 | I15: ○ | J15: 45732 | K15: だいじょばない | L15: =len(E15) -> 287 | N15: =mid(F15,1,find("【特質】",F15)-1) &char(10)&memo!$B$2 -> 【名】塵鬼囃（じんきばやし）jinkibayashi 【番】0013 【出現】子供の家や庭、学校の裏庭、神社の境内 #妖怪 #お化け #怪物 #オリジナル妖怪 #monster #ghost #妖怪好き #浮世絵 #百鬼夜行 | O15: =len(N15) -> 113 | P15: 【特質】その昔、東北のある地方では10歳で成人を迎えるとされていた。 塵鬼囃は人間が10歳の誕生日を迎えた夜、それまでについた嘘の数だけ現れ、人間の周りを取り囲む。 塵ほどに小さな妖怪たちはかすかな声でに「嘘ついたね」「ほんとうのことを話そうよ」と囁く。 | Q15: =len(P15) -> 128 | R15: しかし嘘の数が多いほど、声は大きく、くすくすと笑う音や祭囃子のような不気味な音が混ざることもあるという。 塵鬼囃は、子供が嘘をすべて認めれば、その夜のうちに消える。 だが、一つでも隠したままだと、最後にこう囁いて去る。 「また来年、お祝いに来るね。」 | S15: =len(R15) -> 127 | T15: =len(W15) -> 33 | V15: =len(U15) -> 0 | W15: ただし、翌年の誕生日を迎えることは、決してなかったと言われている。 | Y15: =len(X15) -> 0 | AA15: =len(Z15) -> 0 | AC15: =len(AB15) -> 0
A16: 14 | B16: 天衝夜叉（てんつくやしゃ） | C16: tentsukuyasha | D16: 合戦の跡地 | E16: かつて戦国時代の戦場にて、討ち死にした若き武者の怨念が妖怪と化した。 天を突くような逆立つ髪は、彼の未練と気概の象徴。 意志を持つその髪は戦場で斬られた者たちの魂を飲み込み、強大な妖力を宿すようになった。 天衝夜叉に憑かれた者は、髪が勝手に伸び、うねり、まるで生き物のように動き出す。 最初は驚き戸惑うが、やがてその妖気に慣れると、己の力の象徴として誇るようになる。 その結果、天衝夜叉に憑かれた者は「髪を天に向かって伸ばす」ことを運命づけられ、これが後のリーゼント文化の起源とされている。 天衝夜叉の影響を受けた者は、言葉にも独特の変化が生じる。 天衝夜叉の妖気は、魂を揺さぶり、己の意志を誇張して表現させる力を持つ。 特に言葉を強調し、迫力を増す傾向があり、「よろしく」が「夜露死苦」と変化したのも、天衝夜叉の影響とされる。 一説によれば、ある武士がこの妖怪に取り憑かれた際、自らの誓いを「夜露（夜の露に濡れても）」「死（死を恐れず）」「苦（苦難を乗り越え）」という漢字に込め、血で書き記したことが始まりとされる。 その言葉は代々伝わり、やがて現代のヤンキー文化にも受け継がれていったのだという。 天衝夜叉の存在は今も語り継がれ、リーゼントの者たちの間では 「奴を恐れるな。魂を燃やせば、夜叉も味方する」と信じられている。 鏡に映るリーゼントが微かに動いたら、それは天衝夜叉が見守っている証拠だとも言われる。 | F16: ="【名】" & B16 & C16 &char(10) & "【番】" & text(A16,"0000") & char(10) &"【出現】"&D16& char(10)&"【特質】"& char(10)&E16&char(10)&char(10)&memo!$B$1 -> 【名】天衝夜叉（てんつくやしゃ）tentsukuyasha 【番】0014 【出現】合戦の跡地 【特質】 かつて戦国時代の戦場にて、討ち死にした若き武者の怨念が妖怪と化した。 天を突くような逆立つ髪は、彼の未練と気概の象徴。 意志を持つその髪は戦場で斬られた者たちの魂を飲み込み、強大な妖力を宿すようになった。 天衝夜叉に憑かれた者は、髪が勝手に伸び、うねり、まるで生き物のように動き出す。 最初は驚き戸惑うが、やがてその妖気に慣れると、己の力の象徴として誇るようになる。 その結果、天衝夜叉に憑かれた者は「髪を天に向かって伸ばす」ことを運命づけられ、これが後のリーゼント文化の起源とされている。 天衝夜叉の影響を受けた者は、言葉にも独特の変化が生じる。 天衝夜叉の妖気は、魂を揺さぶり、己の意志を誇張して表現させる力を持つ。 特に言葉を強調し、迫力を増す傾向があり、「よろしく」が「夜露死苦」と変化したのも、天衝夜叉の影響とされる。 一説によれば、ある武士がこの妖怪に取り憑かれた際、自らの誓いを「夜露（夜の露に濡れても）」「死（死を恐れず）」「苦（苦難を乗り越え）」という漢字に込め、血で書き記したことが始まりとされる。 その言葉は代々伝わり、やがて現代のヤンキー文化にも受け継がれていったのだという。 天衝夜叉の存在は今も語り継がれ、リーゼントの者たちの間では 「奴を恐れるな。魂を燃やせば、夜叉も味方する」と信じられている。 鏡に映るリーゼントが微かに動いたら、それは天衝夜叉が見守っている証拠だとも言われる。 #妖怪 #yokai #sumie #monster #ghost | G16: 45695 | H16: 45707 | I16: ○ | J16: 45735 | K16: オリジナル | L16: =len(E16) -> 610 | N16: =mid(F16,1,find("【特質】",F16)-1) &char(10)&memo!$B$2 -> 【名】天衝夜叉（てんつくやしゃ）tentsukuyasha 【番】0014 【出現】合戦の跡地 #妖怪 #お化け #怪物 #オリジナル妖怪 #monster #ghost #妖怪好き #浮世絵 #百鬼夜行 | O16: =len(N16) -> 103 | P16: 【特質】かつて戦国時代の戦場にて、討ち死にした若き武者の怨念が妖怪と化した。 天を突くような逆立つ髪は、彼の未練と気概の象徴。 意志を持つその髪は戦場で斬られた者たちの魂を飲み込み、強大な妖力を宿すようになった。 | Q16: =len(P16) -> 106 | R16: 天衝夜叉に憑かれた者は、髪が勝手に伸び、うねり、まるで生き物のように動き出す。 最初は驚き戸惑うが、やがてその妖気に慣れると己の力の象徴として誇るようになる。 その結果、天衝夜叉に憑かれた者は「髪を天に向かって伸ばす」ことを運命づけられ、これが後のリーゼント文化の起源とされている | S16: =len(R16) -> 140 | T16: =len(W16) -> 118 | U16: 一説によれば、ある武士がこの妖怪に取り憑かれた際、自らの誓いを「夜露（夜の露に濡れても）」「死（死を恐れず）」「苦（苦難を乗り越え）」という漢字に込め、血で書き記したことが始まりとされる。 その言葉は代々伝わり、やがて現代のヤンキー文化にも受け継がれていったのだという。 | V16: =len(U16) -> 135 | W16: 天衝夜叉の影響を受けた者は、言葉にも独特の変化が生じる。 天衝夜叉の妖気は、魂を揺さぶり、己の意志を誇張して表現させる力を持つ。 特に言葉を強調し、迫力を増す傾向があり、「よろしく」が「夜露死苦」と変化したのも、天衝夜叉の影響とされる。 | X16: 天衝夜叉の存在は今も語り継がれ、リーゼントの者たちの間では 「奴を恐れるな。魂を燃やせば、夜叉も味方する」と信じられている。 鏡に映るリーゼントが微かに動いたら、それは天衝夜叉が見守っている証拠だとも言われる。 | Y16: =len(X16) -> 105 | AA16: =len(Z16) -> 0 | AC16: =len(AB16) -> 0
A17: 15 | B17: 白綿潜虫（はくめんせんちゅう） | C17: hakumensenchu | D17: 風の強い野原、戦時中の田舎町、夜の静かな路地裏 | E17: 白綿潜虫は、白い綿毛のように風に乗って漂う小さな妖怪で、気づかぬうちに人の耳や鼻から体内に入り込む。 通常は目に見えないほど小さいが、月明かりの下でかすかに光る姿が確認されることがある。 この妖怪に取り憑かれると、自分の意思とは関係なく、特に身近な家族や大切な人に対して悪口や不満を口にしてしまう。 特に子どもが狙われやすく、親や兄弟に対して思ってもいない冷たい言葉を口にすることが多いとされる。 戦時中の食糧難や不安な生活の中で、母親が必死に作ったご飯に「まずい」と言わせたり、家族の苦労を軽んじるような言葉を吐かせたりするため、「戦火の影をさらに濃くする妖怪」として古くから語られている。 戦時中、とある村の少年が母に向かって「おっかぁの飯はまずい！」と怒鳴った。 母は驚きと悲しみのあまり涙を流したが、少年はなぜそんな言葉を言ったのか自分でも分からなかった。 その夜、村の古老が「鼻をかんでごらん」と少年に助言すると、少年の鼻から白い綿毛のようなものがふわりと飛び出していった。 「あれが白綿潜虫さ。人の心に影を落とす厄介な妖怪じゃ。」 その後、少年は母に心から謝罪し、ようやく元の穏やかな関係に戻ったという。 以来、村では子どもが急に悪口を言い出したら「鼻をかめ！」と教える習慣が生まれたという。 そして、もうひとつの噂 近年になって、白綿潜虫の影響についてもう一つの奇妙な現象が報告されている。 それは、少年が「好きな子」に対して悪口を言ってしまうことがしばしば確認されているという事実だ。 「お前なんか嫌いだ！」 「その髪型、変だな！」 「お前がいると邪魔なんだよ！」 本当はまったくそんな気持ちではないのに、口が勝手に動いてしまう。 大人たちは「また白綿潜虫の仕業か」と首を振るが、妖怪が絡んでいると断言できるのだろうか？ それとも、ただ照れくさくて素直になれないだけなのだろうか…？ | F17: ="【名】" & B17 & C17 &char(10) & "【番】" & text(A17,"0000") & char(10) &"【出現】"&D17& char(10)&"【特質】"& char(10)&E17&char(10)&char(10)&memo!$B$1 -> 【名】白綿潜虫（はくめんせんちゅう）hakumensenchu 【番】0015 【出現】風の強い野原、戦時中の田舎町、夜の静かな路地裏 【特質】 白綿潜虫は、白い綿毛のように風に乗って漂う小さな妖怪で、気づかぬうちに人の耳や鼻から体内に入り込む。 通常は目に見えないほど小さいが、月明かりの下でかすかに光る姿が確認されることがある。 この妖怪に取り憑かれると、自分の意思とは関係なく、特に身近な家族や大切な人に対して悪口や不満を口にしてしまう。 特に子どもが狙われやすく、親や兄弟に対して思ってもいない冷たい言葉を口にすることが多いとされる。 戦時中の食糧難や不安な生活の中で、母親が必死に作ったご飯に「まずい」と言わせたり、家族の苦労を軽んじるような言葉を吐かせたりするため、「戦火の影をさらに濃くする妖怪」として古くから語られている。 戦時中、とある村の少年が母に向かって「おっかぁの飯はまずい！」と怒鳴った。 母は驚きと悲しみのあまり涙を流したが、少年はなぜそんな言葉を言ったのか自分でも分からなかった。 その夜、村の古老が「鼻をかんでごらん」と少年に助言すると、少年の鼻から白い綿毛のようなものがふわりと飛び出していった。 「あれが白綿潜虫さ。人の心に影を落とす厄介な妖怪じゃ。」 その後、少年は母に心から謝罪し、ようやく元の穏やかな関係に戻ったという。 以来、村では子どもが急に悪口を言い出したら「鼻をかめ！」と教える習慣が生まれたという。 そして、もうひとつの噂 近年になって、白綿潜虫の影響についてもう一つの奇妙な現象が報告されている。 それは、少年が「好きな子」に対して悪口を言ってしまうことがしばしば確認されているという事実だ。 「お前なんか嫌いだ！」 「その髪型、変だな！」 「お前がいると邪魔なんだよ！」 本当はまったくそんな気持ちではないのに、口が勝手に動いてしまう。 大人たちは「また白綿潜虫の仕業か」と首を振るが、妖怪が絡んでいると断言できるのだろうか？ それとも、ただ照れくさくて素直になれないだけなのだろうか…？ #妖怪 #yokai #sumie #monster #ghost | G17: 45695 | H17: 45708 | I17: ○ | L17: =len(E17) -> 808 | N17: =mid(F17,1,find("【特質】",F17)-1) &char(10)&memo!$B$2 -> 【名】白綿潜虫（はくめんせんちゅう）hakumensenchu 【番】0015 【出現】風の強い野原、戦時中の田舎町、夜の静かな路地裏 #妖怪 #お化け #怪物 #オリジナル妖怪 #monster #ghost #妖怪好き #浮世絵 #百鬼夜行 | O17: =len(N17) -> 123 | P17: 【特質】白綿潜虫は、白い綿毛のように風に乗って漂う小さな妖怪で、気づかぬうちに人の耳や鼻から体内に入り込む。 通常は目に見えないほど小さいが、月明かりの下でかすかに光る姿が確認されることがある。 この妖怪に取り憑かれると、自分の意思とは関係なく、 | Q17: =len(P17) -> 123 | R17: 特に身近な家族や大切な人に対して悪口や不満を口にしてしまう。 特に子どもが狙われやすく、親や兄弟に対して思ってもいない冷たい言葉を口にすることが多いとされる。 戦時中の食糧難や不安な生活の中で、母親が必死に作ったご飯に「まずい」と言わせたり、 | S17: =len(R17) -> 122 | T17: =len(W17) -> 140 | U17: その夜、村の古老が「鼻をかんでごらん」と少年に助言すると、少年の鼻から白い綿毛のようなものがふわりと飛び出していった。 「あれが白綿潜虫さ。人の心に影を落とす厄介な妖怪じゃ。」 その後、少年は母に心から謝罪し、ようやく元の穏やかな関係に戻ったという。 | V17: =len(U17) -> 128 | W17: 家族の苦労を軽んじるような言葉を吐かせたりするため「戦火の影をさらに濃くする妖怪」として古くから語られている。 戦時中、とある村の少年が母に向かって「おっかぁの飯はまずい！」と怒鳴った。 母は驚きと悲しみのあまり涙を流したが、少年はなぜそんな言葉を言ったのか自分でも分からなかった | X17: 以来、村では子どもが急に悪口を言い出したら「鼻をかめ！」と教える習慣が生まれたという。 そして、もうひとつの噂 近年になって、白綿潜虫の影響についてもう一つの奇妙な現象が報告されている。 | Y17: =len(X17) -> 94 | Z17: それは、少年が「好きな子」に対して悪口を言ってしまうことがしばしば確認されているという事実だ。 「お前なんか嫌いだ！」 「その髪型、変だな！」 「お前がいると邪魔なんだよ！」 本当はまったくそんな気持ちではないのに、口が勝手に動いてしまう。 | AA17: =len(Z17) -> 122 | AC17: =len(AB17) -> 0
A18: 16 | B18: 滴濁濁（てきだくだく） | C18: tekidakudaku | D18: 雨の多い街道や田舎の小道、特に水たまりが広がる場所 | E18: 滴濁濁は水たまりに潜む妖怪で、雨の日やその直後に人々を驚かせることを好む。 水と泥が混ざり合った流動的な体を持ち、大きな目と鋭い牙が特徴的だ。 馬車や車が水たまりを通るたびに、その水しぶきを操り、近くを歩く人々に正確に浴びせかける。 傘を差した者であっても容赦なく水を浴びせ、濡れるのを防ぐ術を笑うかのような振る舞いを見せる。 昔、滴濁濁が頻繁に現れる街道があった。 そこでは雨が降るたびに旅人や行商人たちが被害を受け、水たまりから跳ね上がる泥水で全身を濡らされてしまうことが日常茶飯事だった。 特に傘を差している者ほど狙われる傾向があり、人々は「滴濁濁の仕業だ」と恐れ、雨の日の外出を控えるようになった。 そんな中、一人の知恵者が「傘を使わず、全身を覆う防具を作れば滴濁濁に勝てるのではないか」と考えた。 そして、油を染み込ませた布を縫い合わせ、頭から足先まで覆う雨具を作り出した。 これが後に「雨合羽」と呼ばれるようになる装備だった。 実際に雨合羽を着て滴濁濁の現れる街道を歩いてみると、妖怪はその完全防備の姿に戸惑い、水しぶきを操るも、思うように効果を与えられなかったという。 その結果、雨合羽を着た旅人が増え、滴濁濁が現れる頻度も次第に減少していった。 滴濁濁の伝説は、人々に困難への対処法を考えさせるきっかけとなった象徴的なエピソードだと言われている。 予期せぬ事態に柔軟に対応する知恵と工夫が、日常の生活を快適にする道を切り開くという教訓を秘めている。 | F18: ="【名】" & B18 & C18 &char(10) & "【番】" & text(A18,"0000") & char(10) &"【出現】"&D18& char(10)&"【特質】"& char(10)&E18&char(10)&char(10)&memo!$B$1 -> 【名】滴濁濁（てきだくだく）tekidakudaku 【番】0016 【出現】雨の多い街道や田舎の小道、特に水たまりが広がる場所 【特質】 滴濁濁は水たまりに潜む妖怪で、雨の日やその直後に人々を驚かせることを好む。 水と泥が混ざり合った流動的な体を持ち、大きな目と鋭い牙が特徴的だ。 馬車や車が水たまりを通るたびに、その水しぶきを操り、近くを歩く人々に正確に浴びせかける。 傘を差した者であっても容赦なく水を浴びせ、濡れるのを防ぐ術を笑うかのような振る舞いを見せる。 昔、滴濁濁が頻繁に現れる街道があった。 そこでは雨が降るたびに旅人や行商人たちが被害を受け、水たまりから跳ね上がる泥水で全身を濡らされてしまうことが日常茶飯事だった。 特に傘を差している者ほど狙われる傾向があり、人々は「滴濁濁の仕業だ」と恐れ、雨の日の外出を控えるようになった。 そんな中、一人の知恵者が「傘を使わず、全身を覆う防具を作れば滴濁濁に勝てるのではないか」と考えた。 そして、油を染み込ませた布を縫い合わせ、頭から足先まで覆う雨具を作り出した。 これが後に「雨合羽」と呼ばれるようになる装備だった。 実際に雨合羽を着て滴濁濁の現れる街道を歩いてみると、妖怪はその完全防備の姿に戸惑い、水しぶきを操るも、思うように効果を与えられなかったという。 その結果、雨合羽を着た旅人が増え、滴濁濁が現れる頻度も次第に減少していった。 滴濁濁の伝説は、人々に困難への対処法を考えさせるきっかけとなった象徴的なエピソードだと言われている。 予期せぬ事態に柔軟に対応する知恵と工夫が、日常の生活を快適にする道を切り開くという教訓を秘めている。 #妖怪 #yokai #sumie #monster #ghost | G18: 45696 | H18: 45709 | I18: ○ | L18: =len(E18) -> 636 | N18: =mid(F18,1,find("【特質】",F18)-1) &char(10)&memo!$B$2 -> 【名】滴濁濁（てきだくだく）tekidakudaku 【番】0016 【出現】雨の多い街道や田舎の小道、特に水たまりが広がる場所 #妖怪 #お化け #怪物 #オリジナル妖怪 #monster #ghost #妖怪好き #浮世絵 #百鬼夜行 | O18: =len(N18) -> 120 | P18: 【特質】滴濁濁は水たまりに潜む妖怪で、雨の日やその直後に人々を驚かせることを好む。 水と泥が混ざり合った流動的な体を持ち、大きな目と鋭い牙が特徴的だ。 馬車や車が水たまりを通るたびに、その水しぶきを操り、近くを歩く人々に正確に浴びせかける。 | Q18: =len(P18) -> 120 | R18: 傘を差した者であっても容赦なく水を浴びせ、濡れるのを防ぐ術を笑うかのような振る舞いを見せる。 昔、滴濁濁が頻繁に現れる街道があった。 そこでは雨が降るたびに旅人や行商人たちが被害を受け、水たまりから跳ね上がる泥水で全身を濡らされてしまうことが日常茶飯事だった。 | S18: =len(R18) -> 131 | T18: =len(W18) -> 106 | U18: そして、油を染み込ませた布を縫い合わせ、頭から足先まで覆う雨具を作り出した。 これが後に「雨合羽」と呼ばれるようになる装備だった。 実際に雨合羽を着て滴濁濁の現れる街道を歩いてみると、妖怪はその完全防備の姿に戸惑い、水しぶきを操るも、思うように効果を与えられなかったという。 | V18: =len(U18) -> 138 | W18: 特に傘を差している者ほど狙われる傾向があり、人々は「滴濁濁の仕業だ」と恐れ、雨の日の外出を控えるようになった。 そんな中、一人の知恵者が「傘を使わず、全身を覆う防具を作れば滴濁濁に勝てるのではないか」と考えた。 | X18: その結果、雨合羽を着た旅人が増え、滴濁濁が現れる頻度も次第に減少していった。 滴濁濁の伝説は、人々に困難への対処法を考えさせるきっかけとなった象徴的なエピソードだと言われている。 予期せぬ事態に柔軟に対応する知恵と工夫が、日常の生活を快適にする道を切り開くという教訓を秘めている。 | Y18: =len(X18) -> 140 | AA18: =len(Z18) -> 0 | AC18: =len(AB18) -> 0
A19: 17 | B19: 削哭鬼（けずなき） | C19: kezunaki | D19: 廃れた寺子屋跡、古い学び舎、使われなくなった文房具店 | E19: 削哭鬼は、手回し式の鉛筆削りと融合した幽鬼であり、かつて学び舎に満ちていた知識と執念が形を成した妖怪とされる。 往時の削哭鬼は、鉛筆を差し込んだ者の知識を根こそぎ奪い取り、その学舎を崩壊させるほどの力を持っていた。 削られるごとに持ち主の記憶が霧散し、やがては何も知らぬ者となり果てた。 知識を奪われた者たちは筆を持つことすら忘れ、学びの場は荒廃していったという。 しかし時代が流れ、削哭鬼もまた衰えた。 今や知識を奪う力は薄れ、代わりに削りかすを果てしなく吐き出し続けるだけの存在となってしまった。 その削りかすは黒く滲んだ墨のようで、宙をさまよいながら消えたはずの古文や失われた記録を浮かび上がらせることがある。 そのため、一部の学者や陰陽師たちは、削哭鬼のもたらす削りかすを集め、隠された真実を暴こうとすることもあった。 だが、削哭鬼の嘆きを耳にしてはならない。 かつて奪われた知識への慟哭が、聞く者の記憶を削ぎ落とし、学ぶことの意味すら霞ませてしまうからである。 | F19: ="【名】" & B19 & C19 &char(10) & "【番】" & text(A19,"0000") & char(10) &"【出現】"&D19& char(10)&"【特質】"& char(10)&E19&char(10)&char(10)&memo!$B$1 -> 【名】削哭鬼（けずなき）kezunaki 【番】0017 【出現】廃れた寺子屋跡、古い学び舎、使われなくなった文房具店 【特質】 削哭鬼は、手回し式の鉛筆削りと融合した幽鬼であり、かつて学び舎に満ちていた知識と執念が形を成した妖怪とされる。 往時の削哭鬼は、鉛筆を差し込んだ者の知識を根こそぎ奪い取り、その学舎を崩壊させるほどの力を持っていた。 削られるごとに持ち主の記憶が霧散し、やがては何も知らぬ者となり果てた。 知識を奪われた者たちは筆を持つことすら忘れ、学びの場は荒廃していったという。 しかし時代が流れ、削哭鬼もまた衰えた。 今や知識を奪う力は薄れ、代わりに削りかすを果てしなく吐き出し続けるだけの存在となってしまった。 その削りかすは黒く滲んだ墨のようで、宙をさまよいながら消えたはずの古文や失われた記録を浮かび上がらせることがある。 そのため、一部の学者や陰陽師たちは、削哭鬼のもたらす削りかすを集め、隠された真実を暴こうとすることもあった。 だが、削哭鬼の嘆きを耳にしてはならない。 かつて奪われた知識への慟哭が、聞く者の記憶を削ぎ落とし、学ぶことの意味すら霞ませてしまうからである。 #妖怪 #yokai #sumie #monster #ghost | G19: 45696 | H19: 45710 | I19: ○ | L19: =len(E19) -> 437 | N19: =mid(F19,1,find("【特質】",F19)-1) &char(10)&memo!$B$2 -> 【名】削哭鬼（けずなき）kezunaki 【番】0017 【出現】廃れた寺子屋跡、古い学び舎、使われなくなった文房具店 #妖怪 #お化け #怪物 #オリジナル妖怪 #monster #ghost #妖怪好き #浮世絵 #百鬼夜行 | O19: =len(N19) -> 115 | P19: 【特質】削哭鬼は、手回し式の鉛筆削りと融合した幽鬼であり、かつて学び舎に満ちていた知識と執念が形を成した妖怪とされる。 往時の削哭鬼は、鉛筆を差し込んだ者の知識を根こそぎ奪い取り、その学舎を崩壊させるほどの力を持っていた。 | Q19: =len(P19) -> 111 | R19: 削られるごとに持ち主の記憶が霧散し、やがては何も知らぬ者となり果てた。 知識を奪われた者たちは筆を持つことすら忘れ、学びの場は荒廃していったという。 しかし時代が流れ、削哭鬼もまた衰えた。 | S19: =len(R19) -> 95 | T19: =len(W19) -> 106 | U19: そのため、一部の学者や陰陽師たちは、削哭鬼のもたらす削りかすを集め、隠された真実を暴こうとすることもあった。 だが、削哭鬼の嘆きを耳にしてはならない。 かつて奪われた知識への慟哭が、聞く者の記憶を削ぎ落とし、学ぶことの意味すら霞ませてしまうからである。 | V19: =len(U19) -> 127 | W19: 今や知識を奪う力は薄れ、代わりに削りかすを果てしなく吐き出し続けるだけの存在となってしまった。 その削りかすは黒く滲んだ墨のようで、宙をさまよいながら消えたはずの古文や失われた記録を浮かび上がらせることがある。 | Y19: =len(X19) -> 0 | AA19: =len(Z19) -> 0 | AC19: =len(AB19) -> 0
A20: 18 | B20: 終導珠（しゅうどうしゅ） | C20: shudoshu | D20: 一時代を築いた後の少し寂れたボーリング場 | E20: 投げられ、ぶつけられ、指を入れられ、繰り返し回収される――。 終わることのない扱われ方に、やがて玉は怒りを覚えた。 ある時、玉は意思を持ちはじめた。 人の指が穴に入るたびに微かに震え、爪の垢を吸い取るようになった。 終導珠は、それを集め、煎じ、念じ続けていた。 穢れを蓄え、呪詛を深め、やがて変遷を遂げた玉は、妖怪 「終導珠」 となった。 終導珠は転がらない。 ただそこにあるだけだ。 だが、その穴は深淵へと続く口のように歪み、指を差し込んだ瞬間、魂は囚われる。 指を入れた者は、静かにレーンへ歩み出し、ピンの位置で立ち尽くす。 彼らは悟っている。 その先が地獄の入口であり、一度吸い込まれれば戻れないことを。 そして終導珠は、また誰かが指を入れるのを待ち続ける。 ただそこにありながら。 穢れを集め尽くした時、何に変わるのか――誰も知らない。 | F20: ="【名】" & B20 & C20 &char(10) & "【番】" & text(A20,"0000") & char(10) &"【出現】"&D20& char(10)&"【特質】"& char(10)&E20&char(10)&char(10)&memo!$B$1 -> 【名】終導珠（しゅうどうしゅ）shudoshu 【番】0018 【出現】一時代を築いた後の少し寂れたボーリング場 【特質】 投げられ、ぶつけられ、指を入れられ、繰り返し回収される――。 終わることのない扱われ方に、やがて玉は怒りを覚えた。 ある時、玉は意思を持ちはじめた。 人の指が穴に入るたびに微かに震え、爪の垢を吸い取るようになった。 終導珠は、それを集め、煎じ、念じ続けていた。 穢れを蓄え、呪詛を深め、やがて変遷を遂げた玉は、妖怪 「終導珠」 となった。 終導珠は転がらない。 ただそこにあるだけだ。 だが、その穴は深淵へと続く口のように歪み、指を差し込んだ瞬間、魂は囚われる。 指を入れた者は、静かにレーンへ歩み出し、ピンの位置で立ち尽くす。 彼らは悟っている。 その先が地獄の入口であり、一度吸い込まれれば戻れないことを。 そして終導珠は、また誰かが指を入れるのを待ち続ける。 ただそこにありながら。 穢れを集め尽くした時、何に変わるのか――誰も知らない。 #妖怪 #yokai #sumie #monster #ghost | G20: 45697 | H20: 45711 | I20: ○ | L20: =len(E20) -> 376 | N20: =mid(F20,1,find("【特質】",F20)-1) &char(10)&memo!$B$2 -> 【名】終導珠（しゅうどうしゅ）shudoshu 【番】0018 【出現】一時代を築いた後の少し寂れたボーリング場 #妖怪 #お化け #怪物 #オリジナル妖怪 #monster #ghost #妖怪好き #浮世絵 #百鬼夜行 | O20: =len(N20) -> 112 | P20: 【特質】投げられ、ぶつけられ、指を入れられ、繰り返し回収される――。 終わることのない扱われ方に、やがて玉は怒りを覚えた。 ある時、玉は意思を持ちはじめた。 人の指が穴に入るたびに微かに震え、爪の垢を吸い取るようになった。 終導珠は、それを集め、煎じ、念じ続けていた。 | Q20: =len(P20) -> 135 | R20: 穢れを蓄え、呪詛を深め、やがて変遷を遂げた玉は、妖怪 「終導珠」 となった。 終導珠は転がらない。 ただそこにあるだけだ。 だが、その穴は深淵へと続く口のように歪み、指を差し込んだ瞬間、魂は囚われる。 | S20: =len(R20) -> 101 | T20: =len(W20) -> 140 | V20: =len(U20) -> 0 | W20: 指を入れた者は、静かにレーンへ歩み出し、ピンの位置で立ち尽くす。 彼らは悟っている。 その先が地獄の入口であり、一度吸い込まれれば戻れないことを。 そして終導珠は、また誰かが指を入れるのを待ち続ける。 ただそこにありながら。 穢れを集め尽くした時、何に変わるのか――誰も知らない | Y20: =len(X20) -> 0 | AA20: =len(Z20) -> 0 | AC20: =len(AB20) -> 0
A21: 19 | B21: 亡舞魔離（ぼうぶまり） | C21: bobumari | D21: 霧の立ち込める月夜のジャングルや、風が吹き抜ける祭場跡。 また、音を忘れた者の心の奥深くにも現れるという | E21: 亡舞魔離は、逃げ続ける者の前に現れる妖怪であり、呪われたドラム 「魂の鼓動」 を打ち鳴らす。 この音を聴いた者は抗えず、体が勝手に揺れ始め、やがて踊り続ける亡者となる。 その姿は霧のように儚く、リズムとともに揺れ動く。 どれだけ走っても、どれだけ耳を塞いでも、音からは逃れられない。 亡舞魔離は決して悪意を持たず、むしろ「自分自身と向き合え」という最後の試練を与える存在とも言われる。 彼に囚われないためには、「自分の音を持つこと」が唯一の対処法。 亡舞魔離のビートに飲まれず、自らのリズムを刻める者だけが、呪縛から解き放たれるのだ。 | F21: ="【名】" & B21 & C21 &char(10) & "【番】" & text(A21,"0000") & char(10) &"【出現】"&D21& char(10)&"【特質】"& char(10)&E21&char(10)&char(10)&memo!$B$1 -> 【名】亡舞魔離（ぼうぶまり）bobumari 【番】0019 【出現】霧の立ち込める月夜のジャングルや、風が吹き抜ける祭場跡。 また、音を忘れた者の心の奥深くにも現れるという 【特質】 亡舞魔離は、逃げ続ける者の前に現れる妖怪であり、呪われたドラム 「魂の鼓動」 を打ち鳴らす。 この音を聴いた者は抗えず、体が勝手に揺れ始め、やがて踊り続ける亡者となる。 その姿は霧のように儚く、リズムとともに揺れ動く。 どれだけ走っても、どれだけ耳を塞いでも、音からは逃れられない。 亡舞魔離は決して悪意を持たず、むしろ「自分自身と向き合え」という最後の試練を与える存在とも言われる。 彼に囚われないためには、「自分の音を持つこと」が唯一の対処法。 亡舞魔離のビートに飲まれず、自らのリズムを刻める者だけが、呪縛から解き放たれるのだ。 #妖怪 #yokai #sumie #monster #ghost | G21: 45697 | H21: 45712 | I21: ○ | L21: =len(E21) -> 269 | N21: =mid(F21,1,find("【特質】",F21)-1) &char(10)&memo!$B$2 -> 【名】亡舞魔離（ぼうぶまり）bobumari 【番】0019 【出現】霧の立ち込める月夜のジャングルや、風が吹き抜ける祭場跡。 また、音を忘れた者の心の奥深くにも現れるという #妖怪 #お化け #怪物 #オリジナル妖怪 #monster #ghost #妖怪好き #浮世絵 #百鬼夜行 | O21: =len(N21) -> 143 | P21: 【特質】亡舞魔離は、逃げ続ける者の前に現れる妖怪であり、呪われたドラム 「魂の鼓動」 を打ち鳴らす。 この音を聴いた者は抗えず、体が勝手に揺れ始め、やがて踊り続ける亡者となる。 | Q21: =len(P21) -> 88 | R21: その姿は霧のように儚く、リズムとともに揺れ動く。 どれだけ走っても、どれだけ耳を塞いでも、音からは逃れられない。 亡舞魔離は決して悪意を持たず、むしろ「自分自身と向き合え」という最後の試練を与える存在とも言われる。 | S21: =len(R21) -> 108 | T21: =len(W21) -> 74 | V21: =len(U21) -> 0 | W21: 彼に囚われないためには、「自分の音を持つこと」が唯一の対処法。 亡舞魔離のビートに飲まれず、自らのリズムを刻める者だけが、呪縛から解き放たれるのだ。 | Y21: =len(X21) -> 0 | AA21: =len(Z21) -> 0 | AC21: =len(AB21) -> 0
A22: 20 | B22: 幽眼摘（ゆうがんてき） | C22: yuganteki | D22: 温泉街のとある居酒屋 | E22: 幽眼摘は、おしぼりで脂ぎった顔を拭こうとする中年男性の背後に忍び寄る。 脂ぎった顔を拭おうとしたその刹那、眼球を奪い取る。 特筆すべきは、視神経は残されたままであること。 おしぼりに特殊な粘液を付着させることで、眼球を奪われたことに気づくことはない。 中年男性はいつも通りの行動を続ける。 話は変わるが、この妖怪が現れる居酒屋は、つきだしの旨さで知られている。 他の店ではあまり見かけない、丸くてコリコリとした煮物が供されるのが特徴だ。 ほどよい歯ごたえと濃厚な味付けが絶妙で、酒との相性も抜群。 眼球を奪われた中年男性もまた、そのつきだしを味わう。 ビールで流し込み、満足げに笑みを浮かべる。 またもう一つ話は変わるが、夜にも関わらず隣の目医者が大変賑わうそうだ。 | F22: ="【名】" & B22 & C22 &char(10) & "【番】" & text(A22,"0000") & char(10) &"【出現】"&D22& char(10)&"【特質】"& char(10)&E22&char(10)&char(10)&memo!$B$1 -> 【名】幽眼摘（ゆうがんてき）yuganteki 【番】0020 【出現】温泉街のとある居酒屋 【特質】 幽眼摘は、おしぼりで脂ぎった顔を拭こうとする中年男性の背後に忍び寄る。 脂ぎった顔を拭おうとしたその刹那、眼球を奪い取る。 特筆すべきは、視神経は残されたままであること。 おしぼりに特殊な粘液を付着させることで、眼球を奪われたことに気づくことはない。 中年男性はいつも通りの行動を続ける。 話は変わるが、この妖怪が現れる居酒屋は、つきだしの旨さで知られている。 他の店ではあまり見かけない、丸くてコリコリとした煮物が供されるのが特徴だ。 ほどよい歯ごたえと濃厚な味付けが絶妙で、酒との相性も抜群。 眼球を奪われた中年男性もまた、そのつきだしを味わう。 ビールで流し込み、満足げに笑みを浮かべる。 またもう一つ話は変わるが、夜にも関わらず隣の目医者が大変賑わうそうだ。 #妖怪 #yokai #sumie #monster #ghost | G22: 45697 | H22: 45713 | I22: ○ | L22: =len(E22) -> 336 | N22: =mid(F22,1,find("【特質】",F22)-1) &char(10)&memo!$B$2 -> 【名】幽眼摘（ゆうがんてき）yuganteki 【番】0020 【出現】温泉街のとある居酒屋 #妖怪 #お化け #怪物 #オリジナル妖怪 #monster #ghost #妖怪好き #浮世絵 #百鬼夜行 | O22: =len(N22) -> 102 | P22: 【特質】幽眼摘は、おしぼりで脂ぎった顔を拭こうとする中年男性の背後に忍び寄る。 脂ぎった顔を拭おうとしたその刹那、眼球を奪い取る。 特筆すべきは、視神経は残されたままであること。 おしぼりに特殊な粘液を付着させることで、眼球を奪われたことに気づくことはない。 | Q22: =len(P22) -> 129 | R22: 中年男性はいつも通りの行動を続ける。 話は変わるが、この妖怪が現れる居酒屋は、つきだしの旨さで知られている。 他の店ではあまり見かけない、丸くてコリコリとした煮物が供されるのが特徴だ。 ほどよい歯ごたえと濃厚な味付けが絶妙で、酒との相性も抜群。 | S22: =len(R22) -> 123 | T22: =len(W22) -> 85 | V22: =len(U22) -> 0 | W22: 眼球を奪われた中年男性もまた、そのつきだしを味わう。 ビールで流し込み、満足げに笑みを浮かべる。 またもう一つ話は変わるが、夜にも関わらず隣の目医者が大変賑わうそうだ。 | Y22: =len(X22) -> 0 | AA22: =len(Z22) -> 0 | AC22: =len(AB22) -> 0
A23: 21 | B23: 幽玄十二奏（ゆうげんじゅうにそう） | C23: yugenjuniso | D23: 貴族や武家が密かに催す豪奢な宴、権力者たちが集う隠された楼閣、貴族が放蕩を楽しむ影の茶屋 | E23: 幽玄十二奏は、選ばれし者しか目にすることのできない幻の楽団である。 彼女たちは琵琶、笛、琴、鼓などの楽器を奏で、妖艶な舞や言葉なき歌声で宴を支配する。 その旋律は妖艶かつ甘美で、聴く者の理性を溶かし、本音や欲望を引き出す。 音色に酔いしれた貴族たちは、己の権力を誇示し、これまでに積み重ねてきた悪事を得意げに語り始める。 しかし、演奏が終わると彼女たちは舞台ごと霧のように消え去り、まるで最初から存在しなかったかのように消え失せる。 宴の数日後、どこからともなく彼らが語った秘密が街の噂となる。 最初は些細な囁きだったものが、次第に広まり、やがて公の場で語られるようになる。 そしてついには罪が公になり、信用を失い、破滅へと導かれる。 その結果、町に平和が訪れるのだ。 権力に翻弄され、貴族や権力者に虐げられている町民たちは、幽玄十二奏の存在を噂し、いつか自分たちの街にも現れてくれることを願っているという。 | F23: ="【名】" & B23 & C23 &char(10) & "【番】" & text(A23,"0000") & char(10) &"【出現】"&D23& char(10)&"【特質】"& char(10)&E23&char(10)&char(10)&memo!$B$1 -> 【名】幽玄十二奏（ゆうげんじゅうにそう）yugenjuniso 【番】0021 【出現】貴族や武家が密かに催す豪奢な宴、権力者たちが集う隠された楼閣、貴族が放蕩を楽しむ影の茶屋 【特質】 幽玄十二奏は、選ばれし者しか目にすることのできない幻の楽団である。 彼女たちは琵琶、笛、琴、鼓などの楽器を奏で、妖艶な舞や言葉なき歌声で宴を支配する。 その旋律は妖艶かつ甘美で、聴く者の理性を溶かし、本音や欲望を引き出す。 音色に酔いしれた貴族たちは、己の権力を誇示し、これまでに積み重ねてきた悪事を得意げに語り始める。 しかし、演奏が終わると彼女たちは舞台ごと霧のように消え去り、まるで最初から存在しなかったかのように消え失せる。 宴の数日後、どこからともなく彼らが語った秘密が街の噂となる。 最初は些細な囁きだったものが、次第に広まり、やがて公の場で語られるようになる。 そしてついには罪が公になり、信用を失い、破滅へと導かれる。 その結果、町に平和が訪れるのだ。 権力に翻弄され、貴族や権力者に虐げられている町民たちは、幽玄十二奏の存在を噂し、いつか自分たちの街にも現れてくれることを願っているという。 #妖怪 #yokai #sumie #monster #ghost | G23: 45698 | H23: 45714 | I23: ○ | L23: =len(E23) -> 407 | N23: =mid(F23,1,find("【特質】",F23)-1) &char(10)&memo!$B$2 -> 【名】幽玄十二奏（ゆうげんじゅうにそう）yugenjuniso 【番】0021 【出現】貴族や武家が密かに催す豪奢な宴、権力者たちが集う隠された楼閣、貴族が放蕩を楽しむ影の茶屋 #妖怪 #お化け #怪物 #オリジナル妖怪 #monster #ghost #妖怪好き #浮世絵 #百鬼夜行 | O23: =len(N23) -> 144 | P23: 【特質】幽玄十二奏は、選ばれし者しか目にすることのできない幻の楽団である。 彼女たちは琵琶、笛、琴、鼓などの楽器を奏で、妖艶な舞や言葉なき歌声で宴を支配する。 その旋律は妖艶かつ甘美で、聴く者の理性を溶かし、本音や欲望を引き出す。 | Q23: =len(P23) -> 115 | R23: 音色に酔いしれた貴族たちは、己の権力を誇示し、これまでに積み重ねてきた悪事を得意げに語り始める。 しかし、演奏が終わると彼女たちは舞台ごと霧のように消え去り、まるで最初から存在しなかったかのように消え失せる。 宴の数日後、どこからともなく彼らが語った秘密が街の噂となる。 | S23: =len(R23) -> 136 | T23: =len(W23) -> 86 | U23: 権力に翻弄され、貴族や権力者に虐げられている町民たちは、幽玄十二奏の存在を噂し、いつか自分たちの街にも現れてくれることを願っているという。 | V23: =len(U23) -> 69 | W23: 最初は些細な囁きだったものが、次第に広まり、やがて公の場で語られるようになる。 そしてついには罪が公になり、信用を失い、破滅へと導かれる。 その結果、町に平和が訪れるのだ。 | Y23: =len(X23) -> 0 | AA23: =len(Z23) -> 0 | AC23: =len(AB23) -> 0
A24: 22 | B24: 痰鬼珠（たんぴが） | C24: tampiga | D24: 都市部の流行りのカフェや若者向けの飲食店、特にタピオカドリンクが人気の場所 | E24: 痰鬼珠は、流行に敏感な若い女性たちが集まるカフェやドリンクスタンドにひそむ妖怪である。 一見するとただのタピオカドリンクの中に紛れているが、その実態は「流行を追う人々の欲望」に取り憑く怪異である。 流行りの飲み物を手にし、何も知らずに飲む者の中で痰鬼珠は少しずつ成長する。 最初はただの「美味しい飲み物」だったものが、次第に「もっと飲みたい」「次の新作を試したい」「流行に乗り遅れたくない」という強迫観念へと変わる。 痰鬼珠に憑かれた者は、無意識のうちに新しい流行を追い求め、飲み続けることで自らの意思を失っていく。 やがて痰鬼珠が十分に成長すると、宿主の口から どろりとした黒い痰のような液体を吐き出させ、その中から無数の目が浮かび上がる。 その目は「流行の流れに取り込まれた魂」であり、すでに意思を持たぬ存在となっている。 彼女たちは自分が何を求めていたのかもわからなくなり、ただ次の流行を追い求めて彷徨うことになる。 唯一の対処法は「自分が本当に好きなものを見極めること」である。 痰鬼珠は流行に流されやすい者にしか憑りつけないため、「自分の意志で選んだものを楽しむ」ことで力を失い、ドリンクの中へと消えていく。 しかし、流行の波は次々と押し寄せる。 痰鬼珠が完全に消えることはなく、今日もまた新たなドリンクの中で、不安げに流行を追う者をじっと待っている…。 | F24: ="【名】" & B24 & C24 &char(10) & "【番】" & text(A24,"0000") & char(10) &"【出現】"&D24& char(10)&"【特質】"& char(10)&E24&char(10)&char(10)&memo!$B$1 -> 【名】痰鬼珠（たんぴが）tampiga 【番】0022 【出現】都市部の流行りのカフェや若者向けの飲食店、特にタピオカドリンクが人気の場所 【特質】 痰鬼珠は、流行に敏感な若い女性たちが集まるカフェやドリンクスタンドにひそむ妖怪である。 一見するとただのタピオカドリンクの中に紛れているが、その実態は「流行を追う人々の欲望」に取り憑く怪異である。 流行りの飲み物を手にし、何も知らずに飲む者の中で痰鬼珠は少しずつ成長する。 最初はただの「美味しい飲み物」だったものが、次第に「もっと飲みたい」「次の新作を試したい」「流行に乗り遅れたくない」という強迫観念へと変わる。 痰鬼珠に憑かれた者は、無意識のうちに新しい流行を追い求め、飲み続けることで自らの意思を失っていく。 やがて痰鬼珠が十分に成長すると、宿主の口から どろりとした黒い痰のような液体を吐き出させ、その中から無数の目が浮かび上がる。 その目は「流行の流れに取り込まれた魂」であり、すでに意思を持たぬ存在となっている。 彼女たちは自分が何を求めていたのかもわからなくなり、ただ次の流行を追い求めて彷徨うことになる。 唯一の対処法は「自分が本当に好きなものを見極めること」である。 痰鬼珠は流行に流されやすい者にしか憑りつけないため、「自分の意志で選んだものを楽しむ」ことで力を失い、ドリンクの中へと消えていく。 しかし、流行の波は次々と押し寄せる。 痰鬼珠が完全に消えることはなく、今日もまた新たなドリンクの中で、不安げに流行を追う者をじっと待っている…。 #妖怪 #yokai #sumie #monster #ghost | G24: 45698 | H24: 45715 | I24: ○ | L24: =len(E24) -> 585 | N24: =mid(F24,1,find("【特質】",F24)-1) &char(10)&memo!$B$2 -> 【名】痰鬼珠（たんぴが）tampiga 【番】0022 【出現】都市部の流行りのカフェや若者向けの飲食店、特にタピオカドリンクが人気の場所 #妖怪 #お化け #怪物 #オリジナル妖怪 #monster #ghost #妖怪好き #浮世絵 #百鬼夜行 | O24: =len(N24) -> 125 | P24: 【特質】痰鬼珠は、流行に敏感な若い女性たちが集まるカフェやドリンクスタンドにひそむ妖怪である。 一見するとただのタピオカドリンクの中に紛れているが、その実態は「流行を追う人々の欲望」に取り憑く怪異である。 | Q24: =len(P24) -> 102 | R24: 流行りの飲み物を手にし、何も知らずに飲む者の中で痰鬼珠は少しずつ成長する。 最初はただの「美味しい飲み物」だったものが、次第に「もっと飲みたい」「次の新作を試したい」「流行に乗り遅れたくない」という強迫観念へと変わる。 | S24: =len(R24) -> 109 | T24: =len(W24) -> 113 | U24: その目は「流行の流れに取り込まれた魂」であり、すでに意思を持たぬ存在となっている。 彼女たちは自分が何を求めていたのかもわからなくなり、ただ次の流行を追い求めて彷徨うことになる。 唯一の対処法は「自分が本当に好きなものを見極めること」である。 | V24: =len(U24) -> 121 | W24: 痰鬼珠に憑かれた者は、無意識のうちに新しい流行を追い求め、飲み続けることで自らの意思を失っていく。 やがて痰鬼珠が十分に成長すると、宿主の口から どろりとした黒い痰のような液体を吐き出させ、その中から無数の目が浮かび上がる。 | X24: 痰鬼珠は流行に流されやすい者にしか憑りつけないため、「自分の意志で選んだものを楽しむ」ことで力を失い、ドリンクの中へと消えていく。 しかし、流行の波は次々と押し寄せる。 痰鬼珠が完全に消えることはなく、今日もまた新たなドリンクの中で、不安げに流行を追う者をじっと待っている…。 | Y24: =len(X24) -> 138 | AA24: =len(Z24) -> 0 | AC24: =len(AB24) -> 0
A25: 23 | B25: 幽電鹿（ゆうでんろく） | C25: yudenroku | D25: 都市部の公園、カフェ、電波塔の周辺、Wi-Fiスポットのある駅や商業施設 | E25: 鹿の子のような愛らしい体つきと、ネズミのような素早さを持つ妖怪。 一時のブームにより人に飼い慣らされていたが、やがてブームは過ぎ去り、捨てられた。 いつしかWi-Fiを求めてさまようようになった。 幽電鹿はWi-Fiに繋がっている間だけ、耳が大きく開き、遠くの音まで鮮明に聞き取ることができる。 電波が途切れるとたちまち耳は閉じ、音が遠のくと同時に食欲もなくなり、次のWi-Fiスポットを求めてさまよい続ける。 特に公衆Wi-Fiのあるカフェや駅前に現れることが多く、人々の間をすり抜けるように移動する姿が目撃される。 Wi-Fiに接続すると耳が青白く光り、まるで過去の記憶を辿るかのように目を閉じる。 その光景は、人々がスマホの画面に夢中になる姿とどこか重なるという者もいる。 しかし、圏外に入りWi-Fiを見失うと、幽電鹿は焦るように彷徨い、体が次第に透けていく。 長く繋がれないままでいると、やがて完全に消えてしまうと言われている。 幽電鹿の存在は、都市開発によって行き場を失った野生動物たちを象徴しているともされる。 かつては人間の温もりの中で生きていたが、今は誰も気に留めない電波の影に潜むだけの存在となった。 今日もどこかの街角で、Wi-Fiの波にそっと耳を澄ませる幽電鹿の姿があるかもしれない。 | F25: ="【名】" & B25 & C25 &char(10) & "【番】" & text(A25,"0000") & char(10) &"【出現】"&D25& char(10)&"【特質】"& char(10)&E25&char(10)&char(10)&memo!$B$1 -> 【名】幽電鹿（ゆうでんろく）yudenroku 【番】0023 【出現】都市部の公園、カフェ、電波塔の周辺、Wi-Fiスポットのある駅や商業施設 【特質】 鹿の子のような愛らしい体つきと、ネズミのような素早さを持つ妖怪。 一時のブームにより人に飼い慣らされていたが、やがてブームは過ぎ去り、捨てられた。 いつしかWi-Fiを求めてさまようようになった。 幽電鹿はWi-Fiに繋がっている間だけ、耳が大きく開き、遠くの音まで鮮明に聞き取ることができる。 電波が途切れるとたちまち耳は閉じ、音が遠のくと同時に食欲もなくなり、次のWi-Fiスポットを求めてさまよい続ける。 特に公衆Wi-Fiのあるカフェや駅前に現れることが多く、人々の間をすり抜けるように移動する姿が目撃される。 Wi-Fiに接続すると耳が青白く光り、まるで過去の記憶を辿るかのように目を閉じる。 その光景は、人々がスマホの画面に夢中になる姿とどこか重なるという者もいる。 しかし、圏外に入りWi-Fiを見失うと、幽電鹿は焦るように彷徨い、体が次第に透けていく。 長く繋がれないままでいると、やがて完全に消えてしまうと言われている。 幽電鹿の存在は、都市開発によって行き場を失った野生動物たちを象徴しているともされる。 かつては人間の温もりの中で生きていたが、今は誰も気に留めない電波の影に潜むだけの存在となった。 今日もどこかの街角で、Wi-Fiの波にそっと耳を澄ませる幽電鹿の姿があるかもしれない。 #妖怪 #yokai #sumie #monster #ghost | G25: 45699 | H25: 45716 | I25: ○ | L25: =len(E25) -> 557 | N25: =mid(F25,1,find("【特質】",F25)-1) &char(10)&memo!$B$2 -> 【名】幽電鹿（ゆうでんろく）yudenroku 【番】0023 【出現】都市部の公園、カフェ、電波塔の周辺、Wi-Fiスポットのある駅や商業施設 #妖怪 #お化け #怪物 #オリジナル妖怪 #monster #ghost #妖怪好き #浮世絵 #百鬼夜行 | O25: =len(N25) -> 128 | P25: 【特質】鹿の子のような愛らしい体つきと、ネズミのような素早さを持つ妖怪。 一時のブームにより人に飼い慣らされていたが、やがてブームは過ぎ去り、捨てられた。 いつしかWi-Fiを求めてさまようようになった。 | Q25: =len(P25) -> 102 | R25: 幽電鹿はWi-Fiに繋がっている間だけ、耳が大きく開き、遠くの音まで鮮明に聞き取ることができる。 電波が途切れるとたちまち耳は閉じ、音が遠のくと同時に食欲もなくなり、次のWi-Fiスポットを求めてさまよい続ける。 | S25: =len(R25) -> 106 | T25: =len(W25) -> 134 | U25: しかし、圏外に入りWi-Fiを見失うと、幽電鹿は焦るように彷徨い、体が次第に透けていく。 長く繋がれないままでいると、やがて完全に消えてしまうと言われている。 幽電鹿の存在は、都市開発によって行き場を失った野生動物たちを象徴しているともされる。 | V25: =len(U25) -> 123 | W25: 特に公衆Wi-Fiのあるカフェや駅前に現れることが多く、人々の間をすり抜けるように移動する姿が目撃される。 Wi-Fiに接続すると耳が青白く光り、まるで過去の記憶を辿るかのように目を閉じる。 その光景は、人々がスマホの画面に夢中になる姿とどこか重なるという者もいる。 | X25: かつては人間の温もりの中で生きていたが、今は誰も気に留めない電波の影に潜むだけの存在となった。 今日もどこかの街角で、Wi-Fiの波にそっと耳を澄ませる幽電鹿の姿があるかもしれない。 | Y25: =len(X25) -> 91 | AA25: =len(Z25) -> 0 | AC25: =len(AB25) -> 0
A26: 24 | B26: 飯隠（いがくれ） | C26: igakure | D26: 米どころの田園地帯、農村の穀倉周辺 | E26: おにぎりの姿をした妖怪で、普段は得体のしれない硬い果物の殻に閉じこもっている。 飯隠が殻に籠もる年は、米の収穫が極端に減ると言われ、町人たちは何とかして外に出そうと試行錯誤している。 代々の知恵により、茄子のような紫色に興味を示す ことが分かっている。 紫色の布や茄子の汁を見せると、殻の隙間から僅かに覗くことがあるが、それでも容易には姿を現さない。 無理やり殻から引きずり出そうとすると、左手から垂れる粘液を付着させる。 この粘液は強い呪いの力を持ち、一度触れると しばらく米の味を感じなくなる という恐ろしい影響を及ぼす。 そのため、農民たちは慎重に飯隠を誘い出す方法を模索し続けている。 「飯隠をうまく誘い出せば、米が豊かに実る」 古老たちはそう語るが、いまだに決定的な手段は見つかっていない。 今日もまた、農村では飯隠を誘い出す新たな策が練られている。 | F26: ="【名】" & B26 & C26 &char(10) & "【番】" & text(A26,"0000") & char(10) &"【出現】"&D26& char(10)&"【特質】"& char(10)&E26&char(10)&char(10)&memo!$B$1 -> 【名】飯隠（いがくれ）igakure 【番】0024 【出現】米どころの田園地帯、農村の穀倉周辺 【特質】 おにぎりの姿をした妖怪で、普段は得体のしれない硬い果物の殻に閉じこもっている。 飯隠が殻に籠もる年は、米の収穫が極端に減ると言われ、町人たちは何とかして外に出そうと試行錯誤している。 代々の知恵により、茄子のような紫色に興味を示す ことが分かっている。 紫色の布や茄子の汁を見せると、殻の隙間から僅かに覗くことがあるが、それでも容易には姿を現さない。 無理やり殻から引きずり出そうとすると、左手から垂れる粘液を付着させる。 この粘液は強い呪いの力を持ち、一度触れると しばらく米の味を感じなくなる という恐ろしい影響を及ぼす。 そのため、農民たちは慎重に飯隠を誘い出す方法を模索し続けている。 「飯隠をうまく誘い出せば、米が豊かに実る」 古老たちはそう語るが、いまだに決定的な手段は見つかっていない。 今日もまた、農村では飯隠を誘い出す新たな策が練られている。 #妖怪 #yokai #sumie #monster #ghost | G26: 45699 | H26: 45717 | I26: ○ | L26: =len(E26) -> 383 | N26: =mid(F26,1,find("【特質】",F26)-1) &char(10)&memo!$B$2 -> 【名】飯隠（いがくれ）igakure 【番】0024 【出現】米どころの田園地帯、農村の穀倉周辺 #妖怪 #お化け #怪物 #オリジナル妖怪 #monster #ghost #妖怪好き #浮世絵 #百鬼夜行 | O26: =len(N26) -> 104 | P26: 【特質】おにぎりの姿をした妖怪で、普段は得体のしれない硬い果物の殻に閉じこもっている。 飯隠が殻に籠もる年は、米の収穫が極端に減ると言われ、町人たちは何とかして外に出そうと試行錯誤している。 代々の知恵により、茄子のような紫色に興味を示す ことが分かっている。 | Q26: =len(P26) -> 131 | R26: 紫色の布や茄子の汁を見せると、殻の隙間から僅かに覗くことがあるが、それでも容易には姿を現さない。 無理やり殻から引きずり出そうとすると、左手から垂れる粘液を付着させる。 この粘液は強い呪いの力を持ち、一度触れると しばらく米の味を感じなくなる という恐ろしい影響を及ぼす。 | S26: =len(R26) -> 137 | T26: =len(W26) -> 118 | V26: =len(U26) -> 0 | W26: そのため、農民たちは慎重に飯隠を誘い出す方法を模索し続けている。 「飯隠をうまく誘い出せば、米が豊かに実る」 古老たちはそう語るが、いまだに決定的な手段は見つかっていない。 今日もまた、農村では飯隠を誘い出す新たな策が練られている。 | Y26: =len(X26) -> 0 | AA26: =len(Z26) -> 0 | AC26: =len(AB26) -> 0
A27: 25 | B27: 颯獣翁（そうじゅうのおう） | C27: sojunou | D27: 清掃が行き届いた動物園 | E27: この動物園には、古くから語り継がれる不思議な噂がある。 清掃員だけが見ることのできる妖怪がいるというのだ。 その妖怪は、ライオンのような立派なたてがみを持つ小さな獣で、颯獣翁という。 その姿を拝めるのは、ただ一人。 園を清め、動物たちの住処を守ることを心から愛し、その職務に誇りを持つ者だけだという。 颯獣翁は、そんな清掃員の肩に乗り、共に働く。 たてがみを揺らし、風を起こして塵を払う。 掃き掃除の効率を高め、水しぶきと共に不浄を洗い流す。 だが、その者が掃除の心を失い、園を守る使命から逃れようとするならば、颯獣翁は静かにその肩を離れ、新たな清掃員を探しに行く。 長年この園で働いてきた清掃員は、最後まで颯獣翁に選ばれ続けた。 彼は誰よりも園を愛し、誇りを持って掃除を続けてきたのだ。 しかし、その日が来た。 清掃員が引退を発表したとき、颯獣翁は深い悲しみを抱えながらも、その決断を受け入れた。 職務を全うし、最後まで勤め上げた清掃員の姿に、彼は胸を打たれ、ついに泣きじゃくった。 清掃員もまた、長年寄り添ってくれた妖怪に強い愛着を抱いていた。 別れが寂しくないはずがない。 それでも、彼は最後の清掃を終え、静かに園を後にした。 すでに颯獣翁は肩から消えていた。 だが、そこに残されていたものがあった。 颯獣翁は泣きじゃくった興奮のあまり、清掃員の肩で糞尿を漏らしていたのだ。 清掃員の肩の荷は、まだ下りなかったという。 | F27: ="【名】" & B27 & C27 &char(10) & "【番】" & text(A27,"0000") & char(10) &"【出現】"&D27& char(10)&"【特質】"& char(10)&E27&char(10)&char(10)&memo!$B$1 -> 【名】颯獣翁（そうじゅうのおう）sojunou 【番】0025 【出現】清掃が行き届いた動物園 【特質】 この動物園には、古くから語り継がれる不思議な噂がある。 清掃員だけが見ることのできる妖怪がいるというのだ。 その妖怪は、ライオンのような立派なたてがみを持つ小さな獣で、颯獣翁という。 その姿を拝めるのは、ただ一人。 園を清め、動物たちの住処を守ることを心から愛し、その職務に誇りを持つ者だけだという。 颯獣翁は、そんな清掃員の肩に乗り、共に働く。 たてがみを揺らし、風を起こして塵を払う。 掃き掃除の効率を高め、水しぶきと共に不浄を洗い流す。 だが、その者が掃除の心を失い、園を守る使命から逃れようとするならば、颯獣翁は静かにその肩を離れ、新たな清掃員を探しに行く。 長年この園で働いてきた清掃員は、最後まで颯獣翁に選ばれ続けた。 彼は誰よりも園を愛し、誇りを持って掃除を続けてきたのだ。 しかし、その日が来た。 清掃員が引退を発表したとき、颯獣翁は深い悲しみを抱えながらも、その決断を受け入れた。 職務を全うし、最後まで勤め上げた清掃員の姿に、彼は胸を打たれ、ついに泣きじゃくった。 清掃員もまた、長年寄り添ってくれた妖怪に強い愛着を抱いていた。 別れが寂しくないはずがない。 それでも、彼は最後の清掃を終え、静かに園を後にした。 すでに颯獣翁は肩から消えていた。 だが、そこに残されていたものがあった。 颯獣翁は泣きじゃくった興奮のあまり、清掃員の肩で糞尿を漏らしていたのだ。 清掃員の肩の荷は、まだ下りなかったという。 #妖怪 #yokai #sumie #monster #ghost | G27: 45700 | H27: 45718 | I27: ○ | L27: =len(E27) -> 622 | N27: =mid(F27,1,find("【特質】",F27)-1) &char(10)&memo!$B$2 -> 【名】颯獣翁（そうじゅうのおう）sojunou 【番】0025 【出現】清掃が行き届いた動物園 #妖怪 #お化け #怪物 #オリジナル妖怪 #monster #ghost #妖怪好き #浮世絵 #百鬼夜行 | O27: =len(N27) -> 103 | P27: 【特質】この動物園には、古くから語り継がれる不思議な噂がある。 清掃員だけが見ることのできる妖怪がいるというのだ。 その妖怪は、ライオンのような立派なたてがみを持つ小さな獣で、颯獣翁という。 その姿を拝めるのは、ただ一人。 | Q27: =len(P27) -> 112 | R27: 園を清め、動物たちの住処を守ることを心から愛し、その職務に誇りを持つ者だけだという。 颯獣翁は、そんな清掃員の肩に乗り、共に働く。 たてがみを揺らし、風を起こして塵を払う。 掃き掃除の効率を高め、水しぶきと共に不浄を洗い流す。 | S27: =len(R27) -> 114 | T27: =len(W27) -> 136 | U27: 清掃員が引退を発表したとき、颯獣翁は深い悲しみを抱えながらも、その決断を受け入れた。 職務を全うし、最後まで勤め上げた清掃員の姿に、彼は胸を打たれ、ついに泣きじゃくった。 清掃員もまた、長年寄り添ってくれた妖怪に強い愛着を抱いていた。 別れが寂しくないはずがない。 | V27: =len(U27) -> 134 | W27: だが、その者が掃除の心を失い、園を守る使命から逃れようとするならば、颯獣翁は静かにその肩を離れ、新たな清掃員を探しに行く。 長年この園で働いてきた清掃員は、最後まで颯獣翁に選ばれ続けた。 彼は誰よりも園を愛し、誇りを持って掃除を続けてきたのだ。 しかし、その日が来た。 | X27: それでも、彼は最後の清掃を終え、静かに園を後にした。 すでに颯獣翁は肩から消えていた。 だが、そこに残されていたものがあった。 颯獣翁は泣きじゃくった興奮のあまり、清掃員の肩で糞尿を漏らしていたのだ。 清掃員の肩の荷は、まだ下りなかったという。 | Y27: =len(X27) -> 126 | AA27: =len(Z27) -> 0 | AC27: =len(AB27) -> 0
A28: 26 | B28: 泡幻童（ほうげんどう） | C28: hogendo | D28: 湯屋、銭湯、村の共同風呂など、人々が風呂を楽しむ場所 | E28: ある者が湯を楽しんでいると、突如として現れる泡の妖怪。 泡幻童は、その者が幼き頃に抱いた夢の数だけ泡を生み出す。 泡は次々と膨れ上がり、風呂から溢れ出し、空間全体を白く包み込んでいく。 現れた泡には、かつての夢が映し出される。 剣士を目指していた者は刀を振るう自分を、旅に憧れた者は広大な風景を、商人になりたかった者は繁盛する店を―― しかし、今の自分はどうか？ 現実に追われ、諦め、忘れてしまった夢たち。 湯の中で泡に包まれた者は、次第に懐かしさと悲しみに襲われる。 ふと気づけば、目には涙が滲んでいることもあるだろう。 そのとき、泡幻童はそっと近づき、優しく頭を撫でる。 まるで「夢は消えていない」と囁くように。 次に目を開けると、泡はすべて消え、ただ静かな湯が広がっている。 しかし、その者の心の中には、微かな温もりと、昔の自分がまだどこかにいるという感覚が残るという。 泡幻童は、決して人を脅かす妖怪ではない。 ただ、忘れ去られた夢を、もう一度思い出させるために現れるのだ――。 | F28: ="【名】" & B28 & C28 &char(10) & "【番】" & text(A28,"0000") & char(10) &"【出現】"&D28& char(10)&"【特質】"& char(10)&E28&char(10)&char(10)&memo!$B$1 -> 【名】泡幻童（ほうげんどう）hogendo 【番】0026 【出現】湯屋、銭湯、村の共同風呂など、人々が風呂を楽しむ場所 【特質】 ある者が湯を楽しんでいると、突如として現れる泡の妖怪。 泡幻童は、その者が幼き頃に抱いた夢の数だけ泡を生み出す。 泡は次々と膨れ上がり、風呂から溢れ出し、空間全体を白く包み込んでいく。 現れた泡には、かつての夢が映し出される。 剣士を目指していた者は刀を振るう自分を、旅に憧れた者は広大な風景を、商人になりたかった者は繁盛する店を―― しかし、今の自分はどうか？ 現実に追われ、諦め、忘れてしまった夢たち。 湯の中で泡に包まれた者は、次第に懐かしさと悲しみに襲われる。 ふと気づけば、目には涙が滲んでいることもあるだろう。 そのとき、泡幻童はそっと近づき、優しく頭を撫でる。 まるで「夢は消えていない」と囁くように。 次に目を開けると、泡はすべて消え、ただ静かな湯が広がっている。 しかし、その者の心の中には、微かな温もりと、昔の自分がまだどこかにいるという感覚が残るという。 泡幻童は、決して人を脅かす妖怪ではない。 ただ、忘れ去られた夢を、もう一度思い出させるために現れるのだ――。 #妖怪 #yokai #sumie #monster #ghost | G28: 45700 | H28: 45719 | I28: ○ | L28: =len(E28) -> 448 | N28: =mid(F28,1,find("【特質】",F28)-1) &char(10)&memo!$B$2 -> 【名】泡幻童（ほうげんどう）hogendo 【番】0026 【出現】湯屋、銭湯、村の共同風呂など、人々が風呂を楽しむ場所 #妖怪 #お化け #怪物 #オリジナル妖怪 #monster #ghost #妖怪好き #浮世絵 #百鬼夜行 | O28: =len(N28) -> 116 | P28: 【特質】ある者が湯を楽しんでいると、突如として現れる泡の妖怪。 泡幻童は、その者が幼き頃に抱いた夢の数だけ泡を生み出す。 泡は次々と膨れ上がり、風呂から溢れ出し、空間全体を白く包み込んでいく。 現れた泡には、かつての夢が映し出される。 | Q28: =len(P28) -> 118 | R28: 剣士を目指していた者は刀を振るう自分を、旅に憧れた者は広大な風景を、商人になりたかった者は繁盛する店を―― しかし、今の自分はどうか？ 現実に追われ、諦め、忘れてしまった夢たち。 湯の中で泡に包まれた者は、次第に懐かしさと悲しみに襲われる。 | S28: =len(R28) -> 121 | T28: =len(W28) -> 107 | U28: しかし、その者の心の中には、微かな温もりと、昔の自分がまだどこかにいるという感覚が残るという。 泡幻童は、決して人を脅かす妖怪ではない。 ただ、忘れ去られた夢を、もう一度思い出させるために現れるのだ――。 | V28: =len(U28) -> 103 | W28: ふと気づけば、目には涙が滲んでいることもあるだろう。 そのとき、泡幻童はそっと近づき、優しく頭を撫でる。 まるで「夢は消えていない」と囁くように。 次に目を開けると、泡はすべて消え、ただ静かな湯が広がっている。 | Y28: =len(X28) -> 0 | AA28: =len(Z28) -> 0 | AC28: =len(AB28) -> 0
